Workbook

Sheet Global Stats
A1: Mire ID | B1: Occ totale | C1: Occ H3p | D1: Occ H9 | E1: PicamV3 | F1: Zones
A2: 1 | B2: ='NI202409_CAP-EC_D01'!K3+'NI202409_CAP-EC_D02'!K3+'NI202409_CAP-EC_D03'!K3 -> 625 | C2: ='NI202409_CAP-EC_D01'!K3 -> 289 | D2: ='NI202409_CAP-EC_D02'!K3 -> 257 | E2: ='NI202409_CAP-EC_D03'!K3 -> 79 | F2: 1 | G2: Cap de Nice
A3: 2 | B3: ='NI202409_CAP-EC_D01'!M3+'NI202409_CAP-EC_D02'!M3+'NI202409_CAP-EC_D03'!M3 -> 752 | C3: ='NI202409_CAP-EC_D01'!M3 -> 324 | D3: ='NI202409_CAP-EC_D02'!M3 -> 362 | E3: ='NI202409_CAP-EC_D03'!M3 -> 66 | F3: 1 | G3: Cap de Nice
A4: 3
A5: 4
A6: 5
A7: 6
A8: 7
A9: 8
A10: 9 | B10: ='NI202409_CAP-EC_D01'!O3+'NI202409_CAP-EC_D02'!O3+'NI202409_CAP-EC_D03'!O3 -> 937 | C10: ='NI202409_CAP-EC_D01'!O3 -> 310 | D10: ='NI202409_CAP-EC_D02'!O3 -> 566 | E10: ='NI202409_CAP-EC_D03'!O3 -> 61 | F10: 1 | G10: Cap de Nice
A11: 10 | B11: ='NI202409_CAP-EC_D01'!Q3+'NI202409_CAP-EC_D02'!Q3+'NI202409_CAP-EC_D03'!Q3 -> 427 | C11: ='NI202409_CAP-EC_D01'!Q3 -> 105 | D11: ='NI202409_CAP-EC_D02'!Q3 -> 286 | E11: ='NI202409_CAP-EC_D03'!Q3 -> 36 | F11: 1 | G11: Cap de Nice
A12: 11
A13: 12
A14: 13 | B14: ='NI202409_CAP-EC_D01'!S3+'NI202409_CAP-EC_D02'!S3+'NI202409_CAP-EC_D03'!S3 -> 1066 | C14: ='NI202409_CAP-EC_D01'!S3 -> 381 | D14: ='NI202409_CAP-EC_D02'!S3 -> 606 | E14: ='NI202409_CAP-EC_D03'!S3 -> 79 | F14: 1 | G14: Cap de Nice
A15: 14
A16: 15 | B16: ='NI202409_CAP-EC_D01'!U3+'NI202409_CAP-EC_D02'!U3+'NI202409_CAP-EC_D03'!U3 -> 497 | C16: ='NI202409_CAP-EC_D01'!U3 -> 185 | D16: ='NI202409_CAP-EC_D02'!U3 -> 261 | E16: ='NI202409_CAP-EC_D03'!U3 -> 51 | F16: 1 | G16: Cap de Nice
A17: 16
A18: 17
A19: 18
A20: 19
A21: 20
A22: 21
A23: 22
A24: 23
A25: 24
A26: 25
A27: 26 | B27: ='SR202204_LDM-S_D01'!J3 -> 316 | C27: ='SR202204_LDM-S_D01'!J3 -> 316 | F27: 1 | G27: Sirene
A28: 27
A29: 28 | B29: ='SR202204_LDM-S_D01'!L3 -> 287 | C29: ='SR202204_LDM-S_D01'!L3 -> 287 | F29: 1 | G29: Sirene
A30: 29 | B30: ='SR202204_LDM-S_D01'!N3 -> 198 | C30: ='SR202204_LDM-S_D01'!N3 -> 198 | F30: 1 | G30: Sirene
A31: 30 | B31: ='SR202204_LDM-S_D01'!P3 -> 437 | C31: ='SR202204_LDM-S_D01'!P3 -> 437 | F31: 1 | G31: Sirene
A32: 31
A33: 32
A34: 33 | B34: ='SR202204_LDM-S_D01'!R3 -> 185 | C34: ='SR202204_LDM-S_D01'!R3 -> 185 | F34: 1 | G34: Sirene
A35: 34
A36: 35
A37: 36
A38: 37
A39: 38
A40: 39

Sheet SR202204_LDM-S_D01
A1: The Mermaid Area | B1: Département : | C1: Var | D1: Ville : | E1: Saint-Raphaël | F1: Site : | G1: Lion de Mer, Sirene | H1: Date : | I1: 44657 | J1: ID : | K1: SR202204_LDM-S | L1: Camera : | M1: GoPro H3p | N1: NB Img : | O1: =COUNTA(A4:A1247) -> 1244
A2: Stats | B2: Img avec mire(s) : | C2: =COUNTIF(B4:B1247,"YES") -> 926 | D2: 1 M : | E2: =COUNTIF(C4:C1247,"1") -> 601 | F2: 2 M : | G2: =COUNTIF(C4:C1247,"2") -> 163 | H2: 3 M : | I2: =COUNTIF(C4:C1247,"3") -> 153 | J2: 4 M : | K2: =COUNTIF(C4:C1247,"4") -> 8 | L2: 5 M : | M2: =COUNTIF(C4:C1247,"5") -> 1 | N2: X Ms : | O2: =G2+I2+K2+M2 -> 325
A3: Images name | B3: Mire ? | C3: Quantité | D3: M26 | E3: M28 | F3: M29 | G3: M30 | H3: M33 | I3: M26 occ: | J3: =COUNTIF(D4:I1247,"26") -> 316 | K3: M28 occ: | L3: =COUNTIF(D4:I1247,"28") -> 287 | M3: M29 occ: | N3: =COUNTIF(D4:I1247,"29") -> 198 | O3: M30 occ: | P3: =COUNTIF(D4:I1247,"30") -> 437 | Q3: M33 occ: | R3: =COUNTIF(D4:I1247,"33") -> 185
A4: SR202204_LDM-S_D01_0000.JPG | B4: NO | K4: Combinaisons visibles de mires sur les images
A5: SR202204_LDM-S_D01_0001.JPG | B5: NO | K5: {=UNIQUE(D4:H1247)}
A6: SR202204_LDM-S_D01_0002.JPG | B6: NO | N6: 30 | P6: {=COUNTIF($D$4:$D$1247&"|"&$E$4:$E$1247&"|"&$F$4:$F$1247&"|"&$G$4:$G$1247&"|"&$H$4:$H$1247,$K6&"|"&$L6&"|"&$M6&"|"&$N6&"|"&$O6)} -> 179 | S6: M26 | T6: M28 | U6: M29 | V6: M30 | W6: M33
A7: SR202204_LDM-S_D01_0003.JPG | B7: YES | C7: 1 | G7: 30 | L7: 28 | P7: {=COUNTIF($D$4:$D$1247&"|"&$E$4:$E$1247&"|"&$F$4:$F$1247&"|"&$G$4:$G$1247&"|"&$H$4:$H$1247,$K7&"|"&$L7&"|"&$M7&"|"&$N7&"|"&$O7)} -> 94 | R7: M26 | T7: {=SUM((MMULT(--(K6:O28=26),TRANSPOSE(COLUMN(K6:O6)^0))>0)*(MMULT(--(K6:O28=28),TRANSPOSE(COLUMN(K6:O6)^0))>0)*P6:P28)} -> 180 | U7: {=SUM((MMULT(--(K6:O28=26),TRANSPOSE(COLUMN(K6:O6)^0))>0)*(MMULT(--(K6:O28=29),TRANSPOSE(COLUMN(K6:O6)^0))>0)*P6:P28)} -> 26 | V7: {=SUM((MMULT(--(K6:O28=26),TRANSPOSE(COLUMN(K6:O6)^0))>0)*(MMULT(--(K6:O28=30),TRANSPOSE(COLUMN(K6:O6)^0))>0)*P6:P28)} -> 249 | W7: {=SUM((MMULT(--(K6:O28=26),TRANSPOSE(COLUMN(K6:O6)^0))>0)*(MMULT(--(K6:O28=33),TRANSPOSE(COLUMN(K6:O6)^0))>0)*P6:P28)} -> 19
A8: SR202204_LDM-S_D01_0004.JPG | B8: YES | C8: 1 | G8: 30 | K8: 26 | P8: {=COUNTIF($D$4:$D$1247&"|"&$E$4:$E$1247&"|"&$F$4:$F$1247&"|"&$G$4:$G$1247&"|"&$H$4:$H$1247,$K8&"|"&$L8&"|"&$M8&"|"&$N8&"|"&$O8)} -> 14 | R8: M28 | U8: {=SUM((MMULT(--(K6:O28=28),TRANSPOSE(COLUMN(K6:O6)^0))>0)*(MMULT(--(K6:O28=29),TRANSPOSE(COLUMN(K6:O6)^0))>0)*P6:P28)} -> 6 | V8: {=SUM((MMULT(--(K6:O28=28),TRANSPOSE(COLUMN(K6:O6)^0))>0)*(MMULT(--(K6:O28=30),TRANSPOSE(COLUMN(K6:O6)^0))>0)*P6:P28)} -> 140 | W8: {=SUM((MMULT(--(K6:O28=28),TRANSPOSE(COLUMN(K6:O6)^0))>0)*(MMULT(--(K6:O28=33),TRANSPOSE(COLUMN(K6:O6)^0))>0)*P6:P28)} -> 17
A9: SR202204_LDM-S_D01_0005.JPG | B9: YES | C9: 1 | G9: 30 | K9: 26 | L9: 28 | P9: {=COUNTIF($D$4:$D$1247&"|"&$E$4:$E$1247&"|"&$F$4:$F$1247&"|"&$G$4:$G$1247&"|"&$H$4:$H$1247,$K9&"|"&$L9&"|"&$M9&"|"&$N9&"|"&$O9)} -> 38 | R9: M29 | V9: {=SUM((MMULT(--(K6:O28=29),TRANSPOSE(COLUMN(K6:O6)^0))>0)*(MMULT(--(K6:O28=30),TRANSPOSE(COLUMN(K6:O6)^0))>0)*P6:P28)} -> 28 | W9: {=SUM((MMULT(--(K6:O28=29),TRANSPOSE(COLUMN(K6:O6)^0))>0)*(MMULT(--(K6:O28=33),TRANSPOSE(COLUMN(K6:O6)^0))>0)*P6:P28)} -> 7
A10: SR202204_LDM-S_D01_0006.JPG | B10: YES | C10: 1 | G10: 30 | K10: 26 | N10: 30 | P10: {=COUNTIF($D$4:$D$1247&"|"&$E$4:$E$1247&"|"&$F$4:$F$1247&"|"&$G$4:$G$1247&"|"&$H$4:$H$1247,$K10&"|"&$L10&"|"&$M10&"|"&$N10&"|"&$O10)} -> 92 | R10: M30 | W10: {=SUM((MMULT(--(K6:O28=30),TRANSPOSE(COLUMN(K6:O6)^0))>0)*(MMULT(--(K6:O28=33),TRANSPOSE(COLUMN(K6:O6)^0))>0)*P6:P28)} -> 8
A11: SR202204_LDM-S_D01_0007.JPG | B11: YES | C11: 1 | G11: 30 | M11: 29 | P11: {=COUNTIF($D$4:$D$1247&"|"&$E$4:$E$1247&"|"&$F$4:$F$1247&"|"&$G$4:$G$1247&"|"&$H$4:$H$1247,$K11&"|"&$L11&"|"&$M11&"|"&$N11&"|"&$O11)} -> 163 | R11: M33
A12: SR202204_LDM-S_D01_0008.JPG | B12: YES | C12: 1 | G12: 30 | O12: 33 | P12: {=COUNTIF($D$4:$D$1247&"|"&$E$4:$E$1247&"|"&$F$4:$F$1247&"|"&$G$4:$G$1247&"|"&$H$4:$H$1247,$K12&"|"&$L12&"|"&$M12&"|"&$N12&"|"&$O12)} -> 151
A13: SR202204_LDM-S_D01_0009.JPG | B13: YES | C13: 1 | G13: 30 | L13: 28 | N13: 30 | P13: {=COUNTIF($D$4:$D$1247&"|"&$E$4:$E$1247&"|"&$F$4:$F$1247&"|"&$G$4:$G$1247&"|"&$H$4:$H$1247,$K13&"|"&$L13&"|"&$M13&"|"&$N13&"|"&$O13)} -> 2
A14: SR202204_LDM-S_D01_0010.JPG | B14: YES | C14: 1 | G14: 30 | K14: 26 | L14: 28 | N14: 30 | P14: {=COUNTIF($D$4:$D$1247&"|"&$E$4:$E$1247&"|"&$F$4:$F$1247&"|"&$G$4:$G$1247&"|"&$H$4:$H$1247,$K14&"|"&$L14&"|"&$M14&"|"&$N14&"|"&$O14)} -> 131
A15: SR202204_LDM-S_D01_0011.JPG | B15: YES | C15: 1 | G15: 30 | K15: 26 | N15: 30 | O15: 33 | P15: {=COUNTIF($D$4:$D$1247&"|"&$E$4:$E$1247&"|"&$F$4:$F$1247&"|"&$G$4:$G$1247&"|"&$H$4:$H$1247,$K15&"|"&$L15&"|"&$M15&"|"&$N15&"|"&$O15)} -> 3
A16: SR202204_LDM-S_D01_0012.JPG | B16: YES | C16: 1 | G16: 30 | M16: 29 | O16: 33 | P16: {=COUNTIF($D$4:$D$1247&"|"&$E$4:$E$1247&"|"&$F$4:$F$1247&"|"&$G$4:$G$1247&"|"&$H$4:$H$1247,$K16&"|"&$L16&"|"&$M16&"|"&$N16&"|"&$O16)} -> 3
A17: SR202204_LDM-S_D01_0013.JPG | B17: YES | C17: 1 | G17: 30 | K17: 26 | O17: 33 | P17: {=COUNTIF($D$4:$D$1247&"|"&$E$4:$E$1247&"|"&$F$4:$F$1247&"|"&$G$4:$G$1247&"|"&$H$4:$H$1247,$K17&"|"&$L17&"|"&$M17&"|"&$N17&"|"&$O17)} -> 7
A18: SR202204_LDM-S_D01_0014.JPG | B18: YES | C18: 1 | G18: 30 | L18: 28 | O18: 33 | P18: {=COUNTIF($D$4:$D$1247&"|"&$E$4:$E$1247&"|"&$F$4:$F$1247&"|"&$G$4:$G$1247&"|"&$H$4:$H$1247,$K18&"|"&$L18&"|"&$M18&"|"&$N18&"|"&$O18)} -> 11
A19: SR202204_LDM-S_D01_0015.JPG | B19: YES | C19: 1 | G19: 30 | K19: 26 | L19: 28 | O19: 33 | P19: {=COUNTIF($D$4:$D$1247&"|"&$E$4:$E$1247&"|"&$F$4:$F$1247&"|"&$G$4:$G$1247&"|"&$H$4:$H$1247,$K19&"|"&$L19&"|"&$M19&"|"&$N19&"|"&$O19)} -> 4
A20: SR202204_LDM-S_D01_0016.JPG | B20: YES | C20: 1 | G20: 30 | K20: 26 | L20: 28 | N20: 30 | O20: 33 | P20: {=COUNTIF($D$4:$D$1247&"|"&$E$4:$E$1247&"|"&$F$4:$F$1247&"|"&$G$4:$G$1247&"|"&$H$4:$H$1247,$K20&"|"&$L20&"|"&$M20&"|"&$N20&"|"&$O20)} -> 1
A21: SR202204_LDM-S_D01_0017.JPG | B21: NO | K21: 26 | M21: 29 | O21: 33 | P21: {=COUNTIF($D$4:$D$1247&"|"&$E$4:$E$1247&"|"&$F$4:$F$1247&"|"&$G$4:$G$1247&"|"&$H$4:$H$1247,$K21&"|"&$L21&"|"&$M21&"|"&$N21&"|"&$O21)} -> 1
A22: SR202204_LDM-S_D01_0018.JPG | B22: NO | K22: 26 | M22: 29 | P22: {=COUNTIF($D$4:$D$1247&"|"&$E$4:$E$1247&"|"&$F$4:$F$1247&"|"&$G$4:$G$1247&"|"&$H$4:$H$1247,$K22&"|"&$L22&"|"&$M22&"|"&$N22&"|"&$O22)} -> 3
A23: SR202204_LDM-S_D01_0019.JPG | B23: NO | K23: 26 | L23: 28 | M23: 29 | N23: 30 | P23: {=COUNTIF($D$4:$D$1247&"|"&$E$4:$E$1247&"|"&$F$4:$F$1247&"|"&$G$4:$G$1247&"|"&$H$4:$H$1247,$K23&"|"&$L23&"|"&$M23&"|"&$N23&"|"&$O23)} -> 5
A24: SR202204_LDM-S_D01_0020.JPG | B24: NO | K24: 26 | M24: 29 | N24: 30 | P24: {=COUNTIF($D$4:$D$1247&"|"&$E$4:$E$1247&"|"&$F$4:$F$1247&"|"&$G$4:$G$1247&"|"&$H$4:$H$1247,$K24&"|"&$L24&"|"&$M24&"|"&$N24&"|"&$O24)} -> 14
A25: SR202204_LDM-S_D01_0021.JPG | B25: NO | K25: 26 | L25: 28 | M25: 29 | N25: 30 | O25: 33 | P25: {=COUNTIF($D$4:$D$1247&"|"&$E$4:$E$1247&"|"&$F$4:$F$1247&"|"&$G$4:$G$1247&"|"&$H$4:$H$1247,$K25&"|"&$L25&"|"&$M25&"|"&$N25&"|"&$O25)} -> 1
A26: SR202204_LDM-S_D01_0022.JPG | B26: NO | M26: 29 | N26: 30 | P26: {=COUNTIF($D$4:$D$1247&"|"&$E$4:$E$1247&"|"&$F$4:$F$1247&"|"&$G$4:$G$1247&"|"&$H$4:$H$1247,$K26&"|"&$L26&"|"&$M26&"|"&$N26&"|"&$O26)} -> 6
A27: SR202204_LDM-S_D01_0023.JPG | B27: NO | K27: 26 | M27: 29 | N27: 30 | O27: 33 | P27: {=COUNTIF($D$4:$D$1247&"|"&$E$4:$E$1247&"|"&$F$4:$F$1247&"|"&$G$4:$G$1247&"|"&$H$4:$H$1247,$K27&"|"&$L27&"|"&$M27&"|"&$N27&"|"&$O27)} -> 2
A28: SR202204_LDM-S_D01_0024.JPG | B28: NO | N28: 30 | O28: 33 | P28: {=COUNTIF($D$4:$D$1247&"|"&$E$4:$E$1247&"|"&$F$4:$F$1247&"|"&$G$4:$G$1247&"|"&$H$4:$H$1247,$K28&"|"&$L28&"|"&$M28&"|"&$N28&"|"&$O28)} -> 1
A29: SR202204_LDM-S_D01_0025.JPG | B29: NO | P29: =SUm(P6:P28) -> 926
A30: SR202204_LDM-S_D01_0026.JPG | B30: NO | P30: =C2 -> 926
A31: SR202204_LDM-S_D01_0027.JPG | B31: YES | C31: 1 | E31: 28
A32: SR202204_LDM-S_D01_0028.JPG | B32: YES | C32: 1 | E32: 28
A33: SR202204_LDM-S_D01_0029.JPG | B33: YES | C33: 1 | E33: 28
A34: SR202204_LDM-S_D01_0030.JPG | B34: YES | C34: 1 | E34: 28
A35: SR202204_LDM-S_D01_0031.JPG | B35: YES | C35: 1 | E35: 28
A36: SR202204_LDM-S_D01_0032.JPG | B36: YES | C36: 1 | E36: 28
A37: SR202204_LDM-S_D01_0033.JPG | B37: YES | C37: 1 | E37: 28
A38: SR202204_LDM-S_D01_0034.JPG | B38: YES | C38: 1 | E38: 28
A39: SR202204_LDM-S_D01_0035.JPG | B39: YES | C39: 1 | E39: 28
A40: SR202204_LDM-S_D01_0036.JPG | B40: YES | C40: 1 | E40: 28
...

Sheet NI202409_CAP-EC_D01
A1: The Nice Cape East Cove | B1: Département : | C1: Alpes Maritimes | D1: Ville : | E1: Nice | F1: Site : | G1: Cap de Nice, These | H1: Date : | I1: 45560 | J1: ID : | K1: NI202409_CAP-EC_D01 | L1: Camera : | M1: GoPro H3p | N1: NB Img : | O1: =COUNTA(A4:A3228) -> 3225
A2: Stats | B2: Img avec mire(s) : | C2: =COUNTIF(B4:B3485,"YES") -> 1064 | D2: 1 M : | E2: =COUNTIF(C4:C3485,"1") -> 773 | F2: 2 M : | G2: =COUNTIF(C4:C3485,"2") -> 132 | H2: 3 M : | I2: =COUNTIF(C4:C3485,"3") -> 91 | J2: 4 M : | K2: =COUNTIF(C4:C3485,"4") -> 56 | L2: 5 M : | M2: =COUNTIF(C4:C3485,"5") -> 12 | N2: 6 M : | O2: =COUNTIF(C4:C3485,"6") -> 0 | P2: X Ms : | Q2: =G2+I2+K2+M2+O2 -> 291
A3: Images name | B3: Mire ? | C3: Quantité | D3: M1 | E3: M2 | F3: M9 | G3: M10 | H3: M13 | I3: M15 | J3: M1 occ: | K3: =COUNTIF(D4:J3485,"1") -> 289 | L3: M2 occ: | M3: =COUNTIF(D4:J3485,"2") -> 324 | N3: M9 occ: | O3: =COUNTIF(D4:J3485,"9") -> 310 | P3: M10 occ: | Q3: =COUNTIF(D4:J3485,"10") -> 105 | R3: M13 occ: | S3: =COUNTIF(D4:J3485,"13") -> 381 | T3: M15 occ: | U3: =COUNTIF(D4:J3485,"15") -> 185
A4: G0044570.JPG | B4: NO | L4: Combinaisons visibles de mires sur les images
A5: G0044571.JPG | B5: NO | L5: {=UNIQUE(D4:I3228)}
A6: G0044572.JPG | B6: NO | O6: 10 | R6: {=COUNTIF($D$4:$D$3228&"|"&$E$4:$E$3228&"|"&$F$4:$F$3228&"|"&$G$4:$G$3228&"|"&$H$4:$H$3228&"|"&$I$4:$I$3228,$L6&"|"&$M6&"|"&$N6&"|"&$O6&"|"&$P6&"|"&$Q6)} -> 105 | V6: M1 | W6: M2 | X6: M9 | Y6: M10 | Z6: M13 | AA6: M15
A7: G0044573.JPG | B7: NO | N7: 9 | R7: {=COUNTIF($D$4:$D$3228&"|"&$E$4:$E$3228&"|"&$F$4:$F$3228&"|"&$G$4:$G$3228&"|"&$H$4:$H$3228&"|"&$I$4:$I$3228,$L7&"|"&$M7&"|"&$N7&"|"&$O7&"|"&$P7&"|"&$Q7)} -> 123 | U7: M1 | W7: {=SUM((MMULT(--(L6:Q26=1),TRANSPOSE(COLUMN(L6:Q6)^0))>0)*(MMULT(--(L6:Q26=2),TRANSPOSE(COLUMN(L6:Q6)^0))>0)*R6:R26)} -> 14 | X7: {=SUM((MMULT(--(L6:Q26=1),TRANSPOSE(COLUMN(L6:Q6)^0))>0)*(MMULT(--(L6:Q26=9),TRANSPOSE(COLUMN(L6:Q6)^0))>0)*R6:R26)} -> 38 | Y7: {=SUM((MMULT(--(L6:Q26=1),TRANSPOSE(COLUMN(L6:Q6)^0))>0)*(MMULT(--(L6:Q26=10),TRANSPOSE(COLUMN(L6:Q6)^0))>0)*R6:R26)} -> 0 | Z7: {=SUM((MMULT(--(L6:Q26=1),TRANSPOSE(COLUMN(L6:Q6)^0))>0)*(MMULT(--(L6:Q26=13),TRANSPOSE(COLUMN(L6:Q6)^0))>0)*R6:R26)} -> 83 | AA7: {=SUM((MMULT(--(L6:Q26=1),TRANSPOSE(COLUMN(L6:Q6)^0))>0)*(MMULT(--(L6:Q26=15),TRANSPOSE(COLUMN(L6:Q6)^0))>0)*R6:R26)} -> 84
A8: G0044574.JPG | B8: NO | N8: 9 | P8: 13 | R8: {=COUNTIF($D$4:$D$3228&"|"&$E$4:$E$3228&"|"&$F$4:$F$3228&"|"&$G$4:$G$3228&"|"&$H$4:$H$3228&"|"&$I$4:$I$3228,$L8&"|"&$M8&"|"&$N8&"|"&$O8&"|"&$P8&"|"&$Q8)} -> 47 | U8: M2 | X8: {=SUM((MMULT(--(L6:Q26=2),TRANSPOSE(COLUMN(L6:Q6)^0))>0)*(MMULT(--(L6:Q26=9),TRANSPOSE(COLUMN(L6:Q6)^0))>0)*R6:R26)} -> 98 | Y8: {=SUM((MMULT(--(L6:Q26=2),TRANSPOSE(COLUMN(L6:Q6)^0))>0)*(MMULT(--(L6:Q26=10),TRANSPOSE(COLUMN(L6:Q6)^0))>0)*R6:R26)} -> 0 | Z8: {=SUM((MMULT(--(L6:Q26=2),TRANSPOSE(COLUMN(L6:Q6)^0))>0)*(MMULT(--(L6:Q26=13),TRANSPOSE(COLUMN(L6:Q6)^0))>0)*R6:R26)} -> 125 | AA8: {=SUM((MMULT(--(L6:Q26=2),TRANSPOSE(COLUMN(L6:Q6)^0))>0)*(MMULT(--(L6:Q26=15),TRANSPOSE(COLUMN(L6:Q6)^0))>0)*R6:R26)} -> 45
A9: G0044575.JPG | B9: NO | N9: 9 | P9: 13 | Q9: 15 | R9: {=COUNTIF($D$4:$D$3228&"|"&$E$4:$E$3228&"|"&$F$4:$F$3228&"|"&$G$4:$G$3228&"|"&$H$4:$H$3228&"|"&$I$4:$I$3228,$L9&"|"&$M9&"|"&$N9&"|"&$O9&"|"&$P9&"|"&$Q9)} -> 16 | U9: M9 | Y9: {=SUM((MMULT(--(L6:Q26=9),TRANSPOSE(COLUMN(L6:Q6)^0))>0)*(MMULT(--(L6:Q26=10),TRANSPOSE(COLUMN(L6:Q6)^0))>0)*R6:R26)} -> 0 | Z9: {=SUM((MMULT(--(L6:Q26=9),TRANSPOSE(COLUMN(L6:Q6)^0))>0)*(MMULT(--(L6:Q26=13),TRANSPOSE(COLUMN(L6:Q6)^0))>0)*R6:R26)} -> 182 | AA9: {=SUM((MMULT(--(L6:Q26=9),TRANSPOSE(COLUMN(L6:Q6)^0))>0)*(MMULT(--(L6:Q26=15),TRANSPOSE(COLUMN(L6:Q6)^0))>0)*R6:R26)} -> 83
A10: G0044576.JPG | B10: NO | L10: 1 | N10: 9 | P10: 13 | Q10: 15 | R10: {=COUNTIF($D$4:$D$3228&"|"&$E$4:$E$3228&"|"&$F$4:$F$3228&"|"&$G$4:$G$3228&"|"&$H$4:$H$3228&"|"&$I$4:$I$3228,$L10&"|"&$M10&"|"&$N10&"|"&$O10&"|"&$P10&"|"&$Q10)} -> 23 | U10: M10 | Z10: {=SUM((MMULT(--(L6:Q26=10),TRANSPOSE(COLUMN(L6:Q6)^0))>0)*(MMULT(--(L6:Q26=13),TRANSPOSE(COLUMN(L6:Q6)^0))>0)*R6:R26)} -> 0 | AA10: {=SUM((MMULT(--(L6:Q26=10),TRANSPOSE(COLUMN(L6:Q6)^0))>0)*(MMULT(--(L6:Q26=15),TRANSPOSE(COLUMN(L6:Q6)^0))>0)*R6:R26)} -> 0
A11: G0044577.JPG | B11: NO | L11: 1 | Q11: 15 | R11: {=COUNTIF($D$4:$D$3228&"|"&$E$4:$E$3228&"|"&$F$4:$F$3228&"|"&$G$4:$G$3228&"|"&$H$4:$H$3228&"|"&$I$4:$I$3228,$L11&"|"&$M11&"|"&$N11&"|"&$O11&"|"&$P11&"|"&$Q11)} -> 26 | U11: M13 | AA11: {=SUM((MMULT(--(L6:Q26=13),TRANSPOSE(COLUMN(L6:Q6)^0))>0)*(MMULT(--(L6:Q26=15),TRANSPOSE(COLUMN(L6:Q6)^0))>0)*R6:R26)} -> 109
A12: G0044578.JPG | B12: NO | L12: 1 | R12: {=COUNTIF($D$4:$D$3228&"|"&$E$4:$E$3228&"|"&$F$4:$F$3228&"|"&$G$4:$G$3228&"|"&$H$4:$H$3228&"|"&$I$4:$I$3228,$L12&"|"&$M12&"|"&$N12&"|"&$O12&"|"&$P12&"|"&$Q12)} -> 180 | U12: M15
A13: G0044579.JPG | B13: NO | Q13: 15 | R13: {=COUNTIF($D$4:$D$3228&"|"&$E$4:$E$3228&"|"&$F$4:$F$3228&"|"&$G$4:$G$3228&"|"&$H$4:$H$3228&"|"&$I$4:$I$3228,$L13&"|"&$M13&"|"&$N13&"|"&$O13&"|"&$P13&"|"&$Q13)} -> 50
A14: G0044580.JPG | B14: NO | L14: 1 | P14: 13 | Q14: 15 | R14: {=COUNTIF($D$4:$D$3228&"|"&$E$4:$E$3228&"|"&$F$4:$F$3228&"|"&$G$4:$G$3228&"|"&$H$4:$H$3228&"|"&$I$4:$I$3228,$L14&"|"&$M14&"|"&$N14&"|"&$O14&"|"&$P14&"|"&$Q14)} -> 22
A15: G0044581.JPG | B15: NO | L15: 1 | M15: 2 | P15: 13 | Q15: 15 | R15: {=COUNTIF($D$4:$D$3228&"|"&$E$4:$E$3228&"|"&$F$4:$F$3228&"|"&$G$4:$G$3228&"|"&$H$4:$H$3228&"|"&$I$4:$I$3228,$L15&"|"&$M15&"|"&$N15&"|"&$O15&"|"&$P15&"|"&$Q15)} -> 1
A16: G0044582.JPG | B16: NO | L16: 1 | M16: 2 | N16: 9 | P16: 13 | Q16: 15 | R16: {=COUNTIF($D$4:$D$3228&"|"&$E$4:$E$3228&"|"&$F$4:$F$3228&"|"&$G$4:$G$3228&"|"&$H$4:$H$3228&"|"&$I$4:$I$3228,$L16&"|"&$M16&"|"&$N16&"|"&$O16&"|"&$P16&"|"&$Q16)} -> 12
A17: G0044583.JPG | B17: NO | M17: 2 | N17: 9 | P17: 13 | Q17: 15 | R17: {=COUNTIF($D$4:$D$3228&"|"&$E$4:$E$3228&"|"&$F$4:$F$3228&"|"&$G$4:$G$3228&"|"&$H$4:$H$3228&"|"&$I$4:$I$3228,$L17&"|"&$M17&"|"&$N17&"|"&$O17&"|"&$P17&"|"&$Q17)} -> 32
A18: G0044584.JPG | B18: NO | M18: 2 | N18: 9 | P18: 13 | R18: {=COUNTIF($D$4:$D$3228&"|"&$E$4:$E$3228&"|"&$F$4:$F$3228&"|"&$G$4:$G$3228&"|"&$H$4:$H$3228&"|"&$I$4:$I$3228,$L18&"|"&$M18&"|"&$N18&"|"&$O18&"|"&$P18&"|"&$Q18)} -> 49
A19: G0044585.JPG | B19: NO | M19: 2 | N19: 9 | R19: {=COUNTIF($D$4:$D$3228&"|"&$E$4:$E$3228&"|"&$F$4:$F$3228&"|"&$G$4:$G$3228&"|"&$H$4:$H$3228&"|"&$I$4:$I$3228,$L19&"|"&$M19&"|"&$N19&"|"&$O19&"|"&$P19&"|"&$Q19)} -> 5
A20: G0044586.JPG | B20: NO | L20: 1 | P20: 13 | R20: {=COUNTIF($D$4:$D$3228&"|"&$E$4:$E$3228&"|"&$F$4:$F$3228&"|"&$G$4:$G$3228&"|"&$H$4:$H$3228&"|"&$I$4:$I$3228,$L20&"|"&$M20&"|"&$N20&"|"&$O20&"|"&$P20&"|"&$Q20)} -> 21
A21: G0044587.JPG | B21: NO | P21: 13 | R21: {=COUNTIF($D$4:$D$3228&"|"&$E$4:$E$3228&"|"&$F$4:$F$3228&"|"&$G$4:$G$3228&"|"&$H$4:$H$3228&"|"&$I$4:$I$3228,$L21&"|"&$M21&"|"&$N21&"|"&$O21&"|"&$P21&"|"&$Q21)} -> 121
A22: G0044588.JPG | B22: NO | M22: 2 | P22: 13 | R22: {=COUNTIF($D$4:$D$3228&"|"&$E$4:$E$3228&"|"&$F$4:$F$3228&"|"&$G$4:$G$3228&"|"&$H$4:$H$3228&"|"&$I$4:$I$3228,$L22&"|"&$M22&"|"&$N22&"|"&$O22&"|"&$P22&"|"&$Q22)} -> 30
A23: G0044589.JPG | B23: NO | L23: 1 | M23: 2 | P23: 13 | R23: {=COUNTIF($D$4:$D$3228&"|"&$E$4:$E$3228&"|"&$F$4:$F$3228&"|"&$G$4:$G$3228&"|"&$H$4:$H$3228&"|"&$I$4:$I$3228,$L23&"|"&$M23&"|"&$N23&"|"&$O23&"|"&$P23&"|"&$Q23)} -> 1
A24: G0044590.JPG | B24: NO | P24: 13 | Q24: 15 | R24: {=COUNTIF($D$4:$D$3228&"|"&$E$4:$E$3228&"|"&$F$4:$F$3228&"|"&$G$4:$G$3228&"|"&$H$4:$H$3228&"|"&$I$4:$I$3228,$L24&"|"&$M24&"|"&$N24&"|"&$O24&"|"&$P24&"|"&$Q24)} -> 3
A25: G0044591.JPG | B25: NO | M25: 2 | R25: {=COUNTIF($D$4:$D$3228&"|"&$E$4:$E$3228&"|"&$F$4:$F$3228&"|"&$G$4:$G$3228&"|"&$H$4:$H$3228&"|"&$I$4:$I$3228,$L25&"|"&$M25&"|"&$N25&"|"&$O25&"|"&$P25&"|"&$Q25)} -> 194
A26: G0044592.JPG | B26: NO | L26: 1 | N26: 9 | P26: 13 | R26: {=COUNTIF($D$4:$D$3228&"|"&$E$4:$E$3228&"|"&$F$4:$F$3228&"|"&$G$4:$G$3228&"|"&$H$4:$H$3228&"|"&$I$4:$I$3228,$L26&"|"&$M26&"|"&$N26&"|"&$O26&"|"&$P26&"|"&$Q26)} -> 3
A27: G0044593.JPG | B27: NO | R27: =SUm(R6:R26) -> 1064
A28: G0044594.JPG | B28: NO | R28: =C2 -> 1064
A29: G0044595.JPG | B29: NO
A30: G0044596.JPG | B30: NO
A31: G0044597.JPG | B31: NO
A32: G0044598.JPG | B32: NO
A33: G0044599.JPG | B33: NO
A34: G0044600.JPG | B34: NO
A35: G0044601.JPG | B35: NO
A36: G0044602.JPG | B36: NO
A37: G0044603.JPG | B37: NO
A38: G0044604.JPG | B38: NO
A39: G0044605.JPG | B39: NO
A40: G0044606.JPG | B40: NO
...

Sheet NI202409_CAP-EC_D02
A1: The Nice Cape East Cove | B1: Département : | C1: Alpes Maritimes | D1: Ville : | E1: Nice | F1: Site : | G1: Cap de Nice, These | H1: Date : | I1: 45560 | J1: ID : | K1: NI202409_CAP-EC_D02 | L1: Camera : | M1: GoPro H9 | N1: NB Img : | O1: =COUNTA(A4:A4979)-COUNTIF(B:B,"TRAVEL BACK")-COUNTIF(B:B,"COLOR SAMPLE")-COUNTIF(B:B,"TRASH") -> 2775
A2: Stats | B2: Img avec mire(s) : | C2: =COUNTIF(B4:B7474,"YES") -> 1210 | D2: 1 M : | E2: =COUNTIF(C4:C7474,"1") -> 572 | F2: 2 M : | G2: =COUNTIF(C4:C7474,"2") -> 325 | H2: 3 M : | I2: =COUNTIF(C4:C7474,"3") -> 202 | J2: 4 M : | K2: =COUNTIF(C4:C7474,"4") -> 60 | L2: 5 M : | M2: =COUNTIF(C4:C7474,"5") -> 54 | N2: 6 M : | O2: =COUNTIF(C4:C7474,"6") -> 0 | P2: X Ms : | Q2: =G2+I2+K2+M2+O2 -> 641
A3: Images name | B3: Mire ? | C3: Quantité | D3: M1 | E3: M2 | F3: M9 | G3: M10 | H3: M13 | I3: M15 | J3: M1 occ: | K3: =COUNTIF(D4:J7474,"1") -> 257 | L3: M2 occ: | M3: =COUNTIF(D4:J7474,"2") -> 362 | N3: M9 occ: | O3: =COUNTIF(D4:J7474,"9") -> 566 | P3: M10 occ: | Q3: =COUNTIF(D4:J7474,"10") -> 286 | R3: M13 occ: | S3: =COUNTIF(D4:J7474,"13") -> 606 | T3: M15 occ: | U3: =COUNTIF(D4:J7474,"15") -> 261
A4: G0019167.JPG | B4: TRASH | L4: Combinaisons visibles de mires sur les images
A5: G0019168.JPG | B5: TRASH | L5: {=UNIQUE(D4:I4979)}
A6: G0019169.JPG | B6: TRASH | O6: 10 | R6: {=COUNTIF($D$4:$D$3228&"|"&$E$4:$E$3228&"|"&$F$4:$F$3228&"|"&$G$4:$G$3228&"|"&$H$4:$H$3228&"|"&$I$4:$I$3228,$L6&"|"&$M6&"|"&$N6&"|"&$O6&"|"&$P6&"|"&$Q6)} -> 225 | V6: M1 | W6: M2 | X6: M9 | Y6: M10 | Z6: M13 | AA6: M15
A7: G0019170.JPG | B7: TRASH | N7: 9 | O7: 10 | R7: {=COUNTIF($D$4:$D$3228&"|"&$E$4:$E$3228&"|"&$F$4:$F$3228&"|"&$G$4:$G$3228&"|"&$H$4:$H$3228&"|"&$I$4:$I$3228,$L7&"|"&$M7&"|"&$N7&"|"&$O7&"|"&$P7&"|"&$Q7)} -> 34 | U7: M1 | W7: {=SUM((MMULT(--(L6:Q26=1),TRANSPOSE(COLUMN(L6:Q6)^0))>0)*(MMULT(--(L6:Q26=2),TRANSPOSE(COLUMN(L6:Q6)^0))>0)*R6:R26)} -> 62 | X7: {=SUM((MMULT(--(L6:Q26=1),TRANSPOSE(COLUMN(L6:Q6)^0))>0)*(MMULT(--(L6:Q26=9),TRANSPOSE(COLUMN(L6:Q6)^0))>0)*R6:R26)} -> 103 | Y7: {=SUM((MMULT(--(L6:Q26=1),TRANSPOSE(COLUMN(L6:Q6)^0))>0)*(MMULT(--(L6:Q26=10),TRANSPOSE(COLUMN(L6:Q6)^0))>0)*R6:R26)} -> 0 | Z7: {=SUM((MMULT(--(L6:Q26=1),TRANSPOSE(COLUMN(L6:Q6)^0))>0)*(MMULT(--(L6:Q26=13),TRANSPOSE(COLUMN(L6:Q6)^0))>0)*R6:R26)} -> 139 | AA7: {=SUM((MMULT(--(L6:Q26=1),TRANSPOSE(COLUMN(L6:Q6)^0))>0)*(MMULT(--(L6:Q26=15),TRANSPOSE(COLUMN(L6:Q6)^0))>0)*R6:R26)} -> 149
A8: G0019171.JPG | B8: TRASH | N8: 9 | R8: {=COUNTIF($D$4:$D$3228&"|"&$E$4:$E$3228&"|"&$F$4:$F$3228&"|"&$G$4:$G$3228&"|"&$H$4:$H$3228&"|"&$I$4:$I$3228,$L8&"|"&$M8&"|"&$N8&"|"&$O8&"|"&$P8&"|"&$Q8)} -> 109 | U8: M2 | X8: {=SUM((MMULT(--(L6:Q26=2),TRANSPOSE(COLUMN(L6:Q6)^0))>0)*(MMULT(--(L6:Q26=9),TRANSPOSE(COLUMN(L6:Q6)^0))>0)*R6:R26)} -> 175 | Y8: {=SUM((MMULT(--(L6:Q26=2),TRANSPOSE(COLUMN(L6:Q6)^0))>0)*(MMULT(--(L6:Q26=10),TRANSPOSE(COLUMN(L6:Q6)^0))>0)*R6:R26)} -> 0 | Z8: {=SUM((MMULT(--(L6:Q26=2),TRANSPOSE(COLUMN(L6:Q6)^0))>0)*(MMULT(--(L6:Q26=13),TRANSPOSE(COLUMN(L6:Q6)^0))>0)*R6:R26)} -> 283 | AA8: {=SUM((MMULT(--(L6:Q26=2),TRANSPOSE(COLUMN(L6:Q6)^0))>0)*(MMULT(--(L6:Q26=15),TRANSPOSE(COLUMN(L6:Q6)^0))>0)*R6:R26)} -> 54
A9: G0019172.JPG | B9: TRASH | N9: 9 | Q9: 15 | R9: {=COUNTIF($D$4:$D$3228&"|"&$E$4:$E$3228&"|"&$F$4:$F$3228&"|"&$G$4:$G$3228&"|"&$H$4:$H$3228&"|"&$I$4:$I$3228,$L9&"|"&$M9&"|"&$N9&"|"&$O9&"|"&$P9&"|"&$Q9)} -> 16 | U9: M9 | Y9: {=SUM((MMULT(--(L6:Q26=9),TRANSPOSE(COLUMN(L6:Q6)^0))>0)*(MMULT(--(L6:Q26=10),TRANSPOSE(COLUMN(L6:Q6)^0))>0)*R6:R26)} -> 61 | Z9: {=SUM((MMULT(--(L6:Q26=9),TRANSPOSE(COLUMN(L6:Q6)^0))>0)*(MMULT(--(L6:Q26=13),TRANSPOSE(COLUMN(L6:Q6)^0))>0)*R6:R26)} -> 354 | AA9: {=SUM((MMULT(--(L6:Q26=9),TRANSPOSE(COLUMN(L6:Q6)^0))>0)*(MMULT(--(L6:Q26=15),TRANSPOSE(COLUMN(L6:Q6)^0))>0)*R6:R26)} -> 176
A10: G0019173.JPG | B10: TRASH | N10: 9 | O10: 10 | Q10: 15 | R10: {=COUNTIF($D$4:$D$3228&"|"&$E$4:$E$3228&"|"&$F$4:$F$3228&"|"&$G$4:$G$3228&"|"&$H$4:$H$3228&"|"&$I$4:$I$3228,$L10&"|"&$M10&"|"&$N10&"|"&$O10&"|"&$P10&"|"&$Q10)} -> 27 | U10: M10 | Z10: {=SUM((MMULT(--(L6:Q26=10),TRANSPOSE(COLUMN(L6:Q6)^0))>0)*(MMULT(--(L6:Q26=13),TRANSPOSE(COLUMN(L6:Q6)^0))>0)*R6:R26)} -> 0 | AA10: {=SUM((MMULT(--(L6:Q26=10),TRANSPOSE(COLUMN(L6:Q6)^0))>0)*(MMULT(--(L6:Q26=15),TRANSPOSE(COLUMN(L6:Q6)^0))>0)*R6:R26)} -> 27
A11: G0019174.JPG | B11: TRASH | N11: 9 | P11: 13 | R11: {=COUNTIF($D$4:$D$3228&"|"&$E$4:$E$3228&"|"&$F$4:$F$3228&"|"&$G$4:$G$3228&"|"&$H$4:$H$3228&"|"&$I$4:$I$3228,$L11&"|"&$M11&"|"&$N11&"|"&$O11&"|"&$P11&"|"&$Q11)} -> 100 | U11: M13 | AA11: {=SUM((MMULT(--(L6:Q26=13),TRANSPOSE(COLUMN(L6:Q6)^0))>0)*(MMULT(--(L6:Q26=15),TRANSPOSE(COLUMN(L6:Q6)^0))>0)*R6:R26)} -> 152
A12: G0019175.JPG | B12: TRASH | P12: 13 | Q12: 15 | R12: {=COUNTIF($D$4:$D$3228&"|"&$E$4:$E$3228&"|"&$F$4:$F$3228&"|"&$G$4:$G$3228&"|"&$H$4:$H$3228&"|"&$I$4:$I$3228,$L12&"|"&$M12&"|"&$N12&"|"&$O12&"|"&$P12&"|"&$Q12)} -> 1 | U12: M15
A13: G0019176.JPG | B13: TRASH | N13: 9 | P13: 13 | Q13: 15 | R13: {=COUNTIF($D$4:$D$3228&"|"&$E$4:$E$3228&"|"&$F$4:$F$3228&"|"&$G$4:$G$3228&"|"&$H$4:$H$3228&"|"&$I$4:$I$3228,$L13&"|"&$M13&"|"&$N13&"|"&$O13&"|"&$P13&"|"&$Q13)} -> 39
A14: G0019177.JPG | B14: TRASH | L14: 1 | N14: 9 | P14: 13 | Q14: 15 | R14: {=COUNTIF($D$4:$D$3228&"|"&$E$4:$E$3228&"|"&$F$4:$F$3228&"|"&$G$4:$G$3228&"|"&$H$4:$H$3228&"|"&$I$4:$I$3228,$L14&"|"&$M14&"|"&$N14&"|"&$O14&"|"&$P14&"|"&$Q14)} -> 40
A15: G0019178.JPG | B15: TRASH | L15: 1 | M15: 2 | N15: 9 | P15: 13 | Q15: 15 | R15: {=COUNTIF($D$4:$D$3228&"|"&$E$4:$E$3228&"|"&$F$4:$F$3228&"|"&$G$4:$G$3228&"|"&$H$4:$H$3228&"|"&$I$4:$I$3228,$L15&"|"&$M15&"|"&$N15&"|"&$O15&"|"&$P15&"|"&$Q15)} -> 54
A16: G0019179.JPG | B16: TRASH | P16: 13 | R16: {=COUNTIF($D$4:$D$3228&"|"&$E$4:$E$3228&"|"&$F$4:$F$3228&"|"&$G$4:$G$3228&"|"&$H$4:$H$3228&"|"&$I$4:$I$3228,$L16&"|"&$M16&"|"&$N16&"|"&$O16&"|"&$P16&"|"&$Q16)} -> 93
A17: G0019180.JPG | B17: TRASH | M17: 2 | P17: 13 | R17: {=COUNTIF($D$4:$D$3228&"|"&$E$4:$E$3228&"|"&$F$4:$F$3228&"|"&$G$4:$G$3228&"|"&$H$4:$H$3228&"|"&$I$4:$I$3228,$L17&"|"&$M17&"|"&$N17&"|"&$O17&"|"&$P17&"|"&$Q17)} -> 108
A18: G0019181.JPG | B18: TRASH | M18: 2 | N18: 9 | P18: 13 | R18: {=COUNTIF($D$4:$D$3228&"|"&$E$4:$E$3228&"|"&$F$4:$F$3228&"|"&$G$4:$G$3228&"|"&$H$4:$H$3228&"|"&$I$4:$I$3228,$L18&"|"&$M18&"|"&$N18&"|"&$O18&"|"&$P18&"|"&$Q18)} -> 113
A19: G0019182.JPG | B19: TRASH | L19: 1 | R19: {=COUNTIF($D$4:$D$3228&"|"&$E$4:$E$3228&"|"&$F$4:$F$3228&"|"&$G$4:$G$3228&"|"&$H$4:$H$3228&"|"&$I$4:$I$3228,$L19&"|"&$M19&"|"&$N19&"|"&$O19&"|"&$P19&"|"&$Q19)} -> 75
A20: G0019183.JPG | B20: TRASH | L20: 1 | Q20: 15 | R20: {=COUNTIF($D$4:$D$3228&"|"&$E$4:$E$3228&"|"&$F$4:$F$3228&"|"&$G$4:$G$3228&"|"&$H$4:$H$3228&"|"&$I$4:$I$3228,$L20&"|"&$M20&"|"&$N20&"|"&$O20&"|"&$P20&"|"&$Q20)} -> 37
A21: G0019184.JPG | B21: TRASH | L21: 1 | P21: 13 | Q21: 15 | R21: {=COUNTIF($D$4:$D$3228&"|"&$E$4:$E$3228&"|"&$F$4:$F$3228&"|"&$G$4:$G$3228&"|"&$H$4:$H$3228&"|"&$I$4:$I$3228,$L21&"|"&$M21&"|"&$N21&"|"&$O21&"|"&$P21&"|"&$Q21)} -> 18
A22: G0019185.JPG | B22: TRASH | L22: 1 | P22: 13 | R22: {=COUNTIF($D$4:$D$3228&"|"&$E$4:$E$3228&"|"&$F$4:$F$3228&"|"&$G$4:$G$3228&"|"&$H$4:$H$3228&"|"&$I$4:$I$3228,$L22&"|"&$M22&"|"&$N22&"|"&$O22&"|"&$P22&"|"&$Q22)} -> 19
A23: G0019186.JPG | B23: TRASH | L23: 1 | N23: 9 | R23: {=COUNTIF($D$4:$D$3228&"|"&$E$4:$E$3228&"|"&$F$4:$F$3228&"|"&$G$4:$G$3228&"|"&$H$4:$H$3228&"|"&$I$4:$I$3228,$L23&"|"&$M23&"|"&$N23&"|"&$O23&"|"&$P23&"|"&$Q23)} -> 1
A24: G0019187.JPG | B24: NO | Q24: 15 | R24: {=COUNTIF($D$4:$D$3228&"|"&$E$4:$E$3228&"|"&$F$4:$F$3228&"|"&$G$4:$G$3228&"|"&$H$4:$H$3228&"|"&$I$4:$I$3228,$L24&"|"&$M24&"|"&$N24&"|"&$O24&"|"&$P24&"|"&$Q24)} -> 13
A25: G0019188.JPG | B25: NO | M25: 2 | R25: {=COUNTIF($D$4:$D$3228&"|"&$E$4:$E$3228&"|"&$F$4:$F$3228&"|"&$G$4:$G$3228&"|"&$H$4:$H$3228&"|"&$I$4:$I$3228,$L25&"|"&$M25&"|"&$N25&"|"&$O25&"|"&$P25&"|"&$Q25)} -> 57
A26: G0019189.JPG | B26: NO | L26: 1 | M26: 2 | N26: 9 | P26: 13 | R26: {=COUNTIF($D$4:$D$3228&"|"&$E$4:$E$3228&"|"&$F$4:$F$3228&"|"&$G$4:$G$3228&"|"&$H$4:$H$3228&"|"&$I$4:$I$3228,$L26&"|"&$M26&"|"&$N26&"|"&$O26&"|"&$P26&"|"&$Q26)} -> 8
A27: G0019190.JPG | B27: NO | M27: 2 | N27: 9 | R27: {=COUNTIF($D$4:$D$3228&"|"&$E$4:$E$3228&"|"&$F$4:$F$3228&"|"&$G$4:$G$3228&"|"&$H$4:$H$3228&"|"&$I$4:$I$3228,$L27&"|"&$M27&"|"&$N27&"|"&$O27&"|"&$P27&"|"&$Q27)} -> 9
A28: G0019191.JPG | B28: NO | M28: 2 | N28: 9 | P28: 13 | Q28: 15 | R28: {=COUNTIF($D$4:$D$3228&"|"&$E$4:$E$3228&"|"&$F$4:$F$3228&"|"&$G$4:$G$3228&"|"&$H$4:$H$3228&"|"&$I$4:$I$3228,$L28&"|"&$M28&"|"&$N28&"|"&$O28&"|"&$P28&"|"&$Q28)} -> 12
A29: G0019192.JPG | B29: NO | L29: 1 | M29: 2 | P29: 13 | R29: {=COUNTIF($D$4:$D$3228&"|"&$E$4:$E$3228&"|"&$F$4:$F$3228&"|"&$G$4:$G$3228&"|"&$H$4:$H$3228&"|"&$I$4:$I$3228,$L29&"|"&$M29&"|"&$N29&"|"&$O29&"|"&$P29&"|"&$Q29)} -> 1
A30: G0019193.JPG | B30: NO | L30: 1 | N30: 9 | Q30: 15 | R30: {=COUNTIF($D$4:$D$3228&"|"&$E$4:$E$3228&"|"&$F$4:$F$3228&"|"&$G$4:$G$3228&"|"&$H$4:$H$3228&"|"&$I$4:$I$3228,$L30&"|"&$M30&"|"&$N30&"|"&$O30&"|"&$P30&"|"&$Q30)} -> 4
A31: G0019194.JPG | B31: NO | R31: =SUm(R6:R30) -> 1213
A32: G0019195.JPG | B32: NO | R32: =C2 -> 1210
A33: G0019196.JPG | B33: NO
A34: G0019197.JPG | B34: NO
A35: G0019198.JPG | B35: NO
A36: G0019199.JPG | B36: NO
A37: G0019200.JPG | B37: NO
A38: G0019201.JPG | B38: YES | C38: 1 | G38: 10
A39: G0019202.JPG | B39: YES | C39: 1 | G39: 10
A40: G0019203.JPG | B40: YES | C40: 1 | G40: 10
...

Sheet NI202409_CAP-EC_D03
A1: The Nice Cape East Cove | B1: Département : | C1: Alpes Maritimes | D1: Ville : | E1: Nice | F1: Site : | G1: Cap de Nice, These | H1: Date : | I1: 45560 | J1: ID : | K1: NI202409_CAP-EC_D03 | L1: Camera : | M1: Picam V3 wide (R3 - Rack Cata) | N1: NB Img : | O1: =COUNTA(A4:A5262)-COUNTIF(B:B,"TRAVEL BACK")-COUNTIF(B:B,"COLOR SAMPLE")-COUNTIF(B:B,"TRASH") -> 1262
A2: Stats | B2: Img avec mire(s) : | C2: =COUNTIF(B4:B7757,"YES") -> 279 | D2: 1 M : | E2: =COUNTIF(C4:C7757,"1") -> 228 | F2: 2 M : | G2: =COUNTIF(C4:C7757,"2") -> 20 | H2: 3 M : | I2: =COUNTIF(C4:C7757,"3") -> 21 | J2: 4 M : | K2: =COUNTIF(C4:C7757,"4") -> 9 | L2: 5 M : | M2: =COUNTIF(C4:C7757,"5") -> 1 | N2: 6 M : | O2: =COUNTIF(C4:C7757,"6") -> 0 | P2: X Ms : | Q2: =G2+I2+K2+M2+O2 -> 51
A3: Images name | B3: Mire ? | C3: Quantité | D3: M1 | E3: M2 | F3: M9 | G3: M10 | H3: M13 | I3: M15 | J3: M1 occ: | K3: =COUNTIF(D4:J7757,"1") -> 79 | L3: M2 occ: | M3: =COUNTIF(D4:J7757,"2") -> 66 | N3: M9 occ: | O3: =COUNTIF(D4:J7757,"9") -> 61 | P3: M10 occ: | Q3: =COUNTIF(D4:J7757,"10") -> 36 | R3: M13 occ: | S3: =COUNTIF(D4:J7757,"13") -> 79 | T3: M15 occ: | U3: =COUNTIF(D4:J7757,"15") -> 51
A4: 23-09-24-181335.042-00.jpg | B4: YES | C4: 1 | D4: 1 | L4: Combinaisons visibles de mires sur les images
A5: 23-09-24-181336.900-01.jpg | B5: YES | C5: 1 | D5: 1 | L5: {=UNIQUE(D4:I4979)} -> 1 | R5: {=COUNTIF($D$4:$D$3228&"|"&$E$4:$E$3228&"|"&$F$4:$F$3228&"|"&$G$4:$G$3228&"|"&$H$4:$H$3228&"|"&$I$4:$I$3228,$L5&"|"&$M5&"|"&$N5&"|"&$O5&"|"&$P5&"|"&$Q5)} -> 61
A6: 23-09-24-181338.757-02.jpg | B6: YES | C6: 1 | D6: 1 | V6: M1 | W6: M2 | X6: M9 | Y6: M10 | Z6: M13 | AA6: M15
A7: 23-09-24-181340.624-03.jpg | B7: YES | C7: 1 | D7: 1 | Q7: 15 | R7: {=COUNTIF($D$4:$D$3228&"|"&$E$4:$E$3228&"|"&$F$4:$F$3228&"|"&$G$4:$G$3228&"|"&$H$4:$H$3228&"|"&$I$4:$I$3228,$L7&"|"&$M7&"|"&$N7&"|"&$O7&"|"&$P7&"|"&$Q7)} -> 23 | U7: M1 | W7: {=SUM((MMULT(--(L6:Q26=1),TRANSPOSE(COLUMN(L6:Q6)^0))>0)*(MMULT(--(L6:Q26=2),TRANSPOSE(COLUMN(L6:Q6)^0))>0)*R6:R26)} -> 2 | X7: {=SUM((MMULT(--(L6:Q26=1),TRANSPOSE(COLUMN(L6:Q6)^0))>0)*(MMULT(--(L6:Q26=9),TRANSPOSE(COLUMN(L6:Q6)^0))>0)*R6:R26)} -> 5 | Y7: {=SUM((MMULT(--(L6:Q26=1),TRANSPOSE(COLUMN(L6:Q6)^0))>0)*(MMULT(--(L6:Q26=10),TRANSPOSE(COLUMN(L6:Q6)^0))>0)*R6:R26)} -> 0 | Z7: {=SUM((MMULT(--(L6:Q26=1),TRANSPOSE(COLUMN(L6:Q6)^0))>0)*(MMULT(--(L6:Q26=13),TRANSPOSE(COLUMN(L6:Q6)^0))>0)*R6:R26)} -> 12 | AA7: {=SUM((MMULT(--(L6:Q26=1),TRANSPOSE(COLUMN(L6:Q6)^0))>0)*(MMULT(--(L6:Q26=15),TRANSPOSE(COLUMN(L6:Q6)^0))>0)*R6:R26)} -> 17
A8: 23-09-24-181342.480-04.jpg | B8: YES | C8: 1 | D8: 1 | O8: 10 | R8: {=COUNTIF($D$4:$D$3228&"|"&$E$4:$E$3228&"|"&$F$4:$F$3228&"|"&$G$4:$G$3228&"|"&$H$4:$H$3228&"|"&$I$4:$I$3228,$L8&"|"&$M8&"|"&$N8&"|"&$O8&"|"&$P8&"|"&$Q8)} -> 36 | U8: M2 | X8: {=SUM((MMULT(--(L6:Q26=2),TRANSPOSE(COLUMN(L6:Q6)^0))>0)*(MMULT(--(L6:Q26=9),TRANSPOSE(COLUMN(L6:Q6)^0))>0)*R6:R26)} -> 19 | Y8: {=SUM((MMULT(--(L6:Q26=2),TRANSPOSE(COLUMN(L6:Q6)^0))>0)*(MMULT(--(L6:Q26=10),TRANSPOSE(COLUMN(L6:Q6)^0))>0)*R6:R26)} -> 0 | Z8: {=SUM((MMULT(--(L6:Q26=2),TRANSPOSE(COLUMN(L6:Q6)^0))>0)*(MMULT(--(L6:Q26=13),TRANSPOSE(COLUMN(L6:Q6)^0))>0)*R6:R26)} -> 19 | AA8: {=SUM((MMULT(--(L6:Q26=2),TRANSPOSE(COLUMN(L6:Q6)^0))>0)*(MMULT(--(L6:Q26=15),TRANSPOSE(COLUMN(L6:Q6)^0))>0)*R6:R26)} -> 7
A9: 23-09-24-181344.346-05.jpg | B9: YES | C9: 1 | D9: 1 | N9: 9 | R9: {=COUNTIF($D$4:$D$3228&"|"&$E$4:$E$3228&"|"&$F$4:$F$3228&"|"&$G$4:$G$3228&"|"&$H$4:$H$3228&"|"&$I$4:$I$3228,$L9&"|"&$M9&"|"&$N9&"|"&$O9&"|"&$P9&"|"&$Q9)} -> 27 | U9: M9 | Y9: {=SUM((MMULT(--(L6:Q26=9),TRANSPOSE(COLUMN(L6:Q6)^0))>0)*(MMULT(--(L6:Q26=10),TRANSPOSE(COLUMN(L6:Q6)^0))>0)*R6:R26)} -> 0 | Z9: {=SUM((MMULT(--(L6:Q26=9),TRANSPOSE(COLUMN(L6:Q6)^0))>0)*(MMULT(--(L6:Q26=13),TRANSPOSE(COLUMN(L6:Q6)^0))>0)*R6:R26)} -> 29 | AA9: {=SUM((MMULT(--(L6:Q26=9),TRANSPOSE(COLUMN(L6:Q6)^0))>0)*(MMULT(--(L6:Q26=15),TRANSPOSE(COLUMN(L6:Q6)^0))>0)*R6:R26)} -> 16
A10: 23-09-24-181346.207-06.jpg | B10: YES | C10: 1 | D10: 1 | N10: 9 | P10: 13 | Q10: 15 | R10: {=COUNTIF($D$4:$D$3228&"|"&$E$4:$E$3228&"|"&$F$4:$F$3228&"|"&$G$4:$G$3228&"|"&$H$4:$H$3228&"|"&$I$4:$I$3228,$L10&"|"&$M10&"|"&$N10&"|"&$O10&"|"&$P10&"|"&$Q10)} -> 6 | U10: M10 | Z10: {=SUM((MMULT(--(L6:Q26=10),TRANSPOSE(COLUMN(L6:Q6)^0))>0)*(MMULT(--(L6:Q26=13),TRANSPOSE(COLUMN(L6:Q6)^0))>0)*R6:R26)} -> 0 | AA10: {=SUM((MMULT(--(L6:Q26=10),TRANSPOSE(COLUMN(L6:Q6)^0))>0)*(MMULT(--(L6:Q26=15),TRANSPOSE(COLUMN(L6:Q6)^0))>0)*R6:R26)} -> 0
A11: 23-09-24-181348.056-07.jpg | B11: YES | C11: 1 | D11: 1 | L11: 1 | N11: 9 | P11: 13 | Q11: 15 | R11: {=COUNTIF($D$4:$D$3228&"|"&$E$4:$E$3228&"|"&$F$4:$F$3228&"|"&$G$4:$G$3228&"|"&$H$4:$H$3228&"|"&$I$4:$I$3228,$L11&"|"&$M11&"|"&$N11&"|"&$O11&"|"&$P11&"|"&$Q11)} -> 4 | U11: M13 | AA11: {=SUM((MMULT(--(L6:Q26=13),TRANSPOSE(COLUMN(L6:Q6)^0))>0)*(MMULT(--(L6:Q26=15),TRANSPOSE(COLUMN(L6:Q6)^0))>0)*R6:R26)} -> 21
A12: 23-09-24-181349.916-08.jpg | B12: YES | C12: 1 | D12: 1 | L12: 1 | Q12: 15 | R12: {=COUNTIF($D$4:$D$3228&"|"&$E$4:$E$3228&"|"&$F$4:$F$3228&"|"&$G$4:$G$3228&"|"&$H$4:$H$3228&"|"&$I$4:$I$3228,$L12&"|"&$M12&"|"&$N12&"|"&$O12&"|"&$P12&"|"&$Q12)} -> 6 | U12: M15
A13: 23-09-24-181351.762-09.jpg | B13: YES | C13: 1 | D13: 1 | L13: 1 | P13: 13 | Q13: 15 | R13: {=COUNTIF($D$4:$D$3228&"|"&$E$4:$E$3228&"|"&$F$4:$F$3228&"|"&$G$4:$G$3228&"|"&$H$4:$H$3228&"|"&$I$4:$I$3228,$L13&"|"&$M13&"|"&$N13&"|"&$O13&"|"&$P13&"|"&$Q13)} -> 5
A14: 23-09-24-181353.630-10.jpg | B14: YES | C14: 1 | D14: 1 | L14: 1 | M14: 2 | P14: 13 | Q14: 15 | R14: {=COUNTIF($D$4:$D$3228&"|"&$E$4:$E$3228&"|"&$F$4:$F$3228&"|"&$G$4:$G$3228&"|"&$H$4:$H$3228&"|"&$I$4:$I$3228,$L14&"|"&$M14&"|"&$N14&"|"&$O14&"|"&$P14&"|"&$Q14)} -> 1
A15: 23-09-24-181355.490-11.jpg | B15: YES | C15: 1 | D15: 1 | L15: 1 | M15: 2 | N15: 9 | P15: 13 | Q15: 15 | R15: {=COUNTIF($D$4:$D$3228&"|"&$E$4:$E$3228&"|"&$F$4:$F$3228&"|"&$G$4:$G$3228&"|"&$H$4:$H$3228&"|"&$I$4:$I$3228,$L15&"|"&$M15&"|"&$N15&"|"&$O15&"|"&$P15&"|"&$Q15)} -> 1
A16: 23-09-24-181357.354-12.jpg | B16: YES | C16: 1 | D16: 1 | M16: 2 | N16: 9 | P16: 13 | Q16: 15 | R16: {=COUNTIF($D$4:$D$3228&"|"&$E$4:$E$3228&"|"&$F$4:$F$3228&"|"&$G$4:$G$3228&"|"&$H$4:$H$3228&"|"&$I$4:$I$3228,$L16&"|"&$M16&"|"&$N16&"|"&$O16&"|"&$P16&"|"&$Q16)} -> 4
A17: 23-09-24-181359.224-13.jpg | B17: YES | C17: 1 | D17: 1 | M17: 2 | N17: 9 | P17: 13 | R17: {=COUNTIF($D$4:$D$3228&"|"&$E$4:$E$3228&"|"&$F$4:$F$3228&"|"&$G$4:$G$3228&"|"&$H$4:$H$3228&"|"&$I$4:$I$3228,$L17&"|"&$M17&"|"&$N17&"|"&$O17&"|"&$P17&"|"&$Q17)} -> 9
A18: 23-09-24-181401.092-14.jpg | B18: YES | C18: 1 | D18: 1 | N18: 9 | P18: 13 | R18: {=COUNTIF($D$4:$D$3228&"|"&$E$4:$E$3228&"|"&$F$4:$F$3228&"|"&$G$4:$G$3228&"|"&$H$4:$H$3228&"|"&$I$4:$I$3228,$L18&"|"&$M18&"|"&$N18&"|"&$O18&"|"&$P18&"|"&$Q18)} -> 5
A19: 23-09-24-181402.942-15.jpg | B19: YES | C19: 1 | D19: 1 | M19: 2 | N19: 9 | R19: {=COUNTIF($D$4:$D$3228&"|"&$E$4:$E$3228&"|"&$F$4:$F$3228&"|"&$G$4:$G$3228&"|"&$H$4:$H$3228&"|"&$I$4:$I$3228,$L19&"|"&$M19&"|"&$N19&"|"&$O19&"|"&$P19&"|"&$Q19)} -> 4
A20: 23-09-24-181404.792-16.jpg | B20: YES | C20: 1 | D20: 1 | P20: 13 | R20: {=COUNTIF($D$4:$D$3228&"|"&$E$4:$E$3228&"|"&$F$4:$F$3228&"|"&$G$4:$G$3228&"|"&$H$4:$H$3228&"|"&$I$4:$I$3228,$L20&"|"&$M20&"|"&$N20&"|"&$O20&"|"&$P20&"|"&$Q20)} -> 39
A21: 23-09-24-181406.654-17.jpg | B21: YES | C21: 1 | D21: 1 | M21: 2 | N21: 9 | Q21: 15 | R21: {=COUNTIF($D$4:$D$3228&"|"&$E$4:$E$3228&"|"&$F$4:$F$3228&"|"&$G$4:$G$3228&"|"&$H$4:$H$3228&"|"&$I$4:$I$3228,$L21&"|"&$M21&"|"&$N21&"|"&$O21&"|"&$P21&"|"&$Q21)} -> 1
A22: 23-09-24-181408.498-18.jpg | B22: YES | C22: 1 | D22: 1 | M22: 2 | P22: 13 | R22: {=COUNTIF($D$4:$D$3228&"|"&$E$4:$E$3228&"|"&$F$4:$F$3228&"|"&$G$4:$G$3228&"|"&$H$4:$H$3228&"|"&$I$4:$I$3228,$L22&"|"&$M22&"|"&$N22&"|"&$O22&"|"&$P22&"|"&$Q22)} -> 4
A23: 23-09-24-181410.351-19.jpg | B23: NO | L23: 1 | P23: 13 | R23: {=COUNTIF($D$4:$D$3228&"|"&$E$4:$E$3228&"|"&$F$4:$F$3228&"|"&$G$4:$G$3228&"|"&$H$4:$H$3228&"|"&$I$4:$I$3228,$L23&"|"&$M23&"|"&$N23&"|"&$O23&"|"&$P23&"|"&$Q23)} -> 1
A24: 23-09-24-181412.211-20.jpg | B24: NO | M24: 2 | R24: {=COUNTIF($D$4:$D$3228&"|"&$E$4:$E$3228&"|"&$F$4:$F$3228&"|"&$G$4:$G$3228&"|"&$H$4:$H$3228&"|"&$I$4:$I$3228,$L24&"|"&$M24&"|"&$N24&"|"&$O24&"|"&$P24&"|"&$Q24)} -> 42
A25: 23-09-24-181414.073-21.jpg | B25: NO | R25: =SUm(R5:R24) -> 279
A26: 23-09-24-181415.932-22.jpg | B26: NO | R26: =$C$2 -> 279
A27: 23-09-24-181417.782-23.jpg | B27: NO
A28: 23-09-24-181419.640-24.jpg | B28: NO
A29: 23-09-24-181421.492-25.jpg | B29: NO
A30: 23-09-24-181423.355-26.jpg | B30: NO
A31: 23-09-24-181425.228-27.jpg | B31: NO
A32: 23-09-24-181427.098-28.jpg | B32: YES | C32: 1 | I32: 15
A33: 23-09-24-181428.969-29.jpg | B33: YES | C33: 1 | I33: 15
A34: 23-09-24-181430.848-30.jpg | B34: YES | C34: 1 | I34: 15
A35: 23-09-24-181432.727-31.jpg | B35: YES | C35: 1 | I35: 15
A36: 23-09-24-181435.697-32.jpg | B36: YES | C36: 1 | I36: 15
A37: 23-09-24-181437.572-33.jpg | B37: YES | C37: 1 | I37: 15
A38: 23-09-24-181439.444-34.jpg | B38: YES | C38: 1 | I38: 15
A39: 23-09-24-181441.312-35.jpg | B39: YES | C39: 1 | I39: 15
A40: 23-09-24-181443.190-36.jpg | B40: NO
...

Sheet NI202409_CAP-EC_D04
A1: The Nice Cape East Cove | B1: Département : | C1: Alpes Maritimes | D1: Ville : | E1: Nice | F1: Site : | G1: Cap de Nice, These | H1: Date : | I1: 45560 | J1: ID : | K1: NI202409_CAP-EC_D04 | L1: Camera : | M1: Picam HQ 170°Lens (amazon) (R5 - Rack Main) | N1: NB Img : | O1: =COUNTA(A4:A5262)-COUNTIF(B:B,"TRAVEL BACK")-COUNTIF(B:B,"COLOR SAMPLE")-COUNTIF(B:B,"TRASH") -> 631
A2: Stats | B2: Img avec mire(s) : | C2: =COUNTIF(B4:B7757,"YES") -> 307 | D2: 1 M : | E2: =COUNTIF(C4:C7757,"1") -> 97 | F2: 2 M : | G2: =COUNTIF(C4:C7757,"2") -> 89 | H2: 3 M : | I2: =COUNTIF(C4:C7757,"3") -> 65 | J2: 4 M : | K2: =COUNTIF(C4:C7757,"4") -> 26 | L2: 5 M : | M2: =COUNTIF(C4:C7757,"5") -> 30 | N2: 6 M : | O2: =COUNTIF(C4:C7757,"6") -> 0 | P2: X Ms : | Q2: =G2+I2+K2+M2+O2 -> 210
A3: Images name | B3: Mire ? | C3: Quantité | D3: M1 | E3: M2 | F3: M9 | G3: M10 | H3: M13 | I3: M15 | J3: M1 occ: | K3: =COUNTIF(D4:J7757,"1") -> 84 | L3: M2 occ: | M3: =COUNTIF(D4:J7757,"2") -> 135 | N3: M9 occ: | O3: =COUNTIF(D4:J7757,"9") -> 146 | P3: M10 occ: | Q3: =COUNTIF(D4:J7757,"10") -> 89 | R3: M13 occ: | S3: =COUNTIF(D4:J7757,"13") -> 169 | T3: M15 occ: | U3: =COUNTIF(D4:J7757,"15") -> 100
A4: 23-09-24-184800.757-00.jpg | B4: TRASH | L4: Combinaisons visibles de mires sur les images
A5: 23-09-24-184802.953-01.jpg | B5: TRASH | L5: {=UNIQUE(D4:I4979)}
A6: 23-09-24-184805.150-02.jpg | B6: TRASH | O6: 10 | R6: {=COUNTIF($D$4:$D$3228&"|"&$E$4:$E$3228&"|"&$F$4:$F$3228&"|"&$G$4:$G$3228&"|"&$H$4:$H$3228&"|"&$I$4:$I$3228,$L6&"|"&$M6&"|"&$N6&"|"&$O6&"|"&$P6&"|"&$Q6)} -> 51 | V6: M1 | W6: M2 | X6: M9 | Y6: M10 | Z6: M13 | AA6: M15
A7: 23-09-24-184807.343-03.jpg | B7: TRASH | N7: 9 | O7: 10 | R7: {=COUNTIF($D$4:$D$3228&"|"&$E$4:$E$3228&"|"&$F$4:$F$3228&"|"&$G$4:$G$3228&"|"&$H$4:$H$3228&"|"&$I$4:$I$3228,$L7&"|"&$M7&"|"&$N7&"|"&$O7&"|"&$P7&"|"&$Q7)} -> 13 | U7: M1 | W7: {=SUM((MMULT(--(L6:Q26=1),TRANSPOSE(COLUMN(L6:Q6)^0))>0)*(MMULT(--(L6:Q26=2),TRANSPOSE(COLUMN(L6:Q6)^0))>0)*R6:R26)} -> 31 | X7: {=SUM((MMULT(--(L6:Q26=1),TRANSPOSE(COLUMN(L6:Q6)^0))>0)*(MMULT(--(L6:Q26=9),TRANSPOSE(COLUMN(L6:Q6)^0))>0)*R6:R26)} -> 49 | Y7: {=SUM((MMULT(--(L6:Q26=1),TRANSPOSE(COLUMN(L6:Q6)^0))>0)*(MMULT(--(L6:Q26=10),TRANSPOSE(COLUMN(L6:Q6)^0))>0)*R6:R26)} -> 0 | Z7: {=SUM((MMULT(--(L6:Q26=1),TRANSPOSE(COLUMN(L6:Q6)^0))>0)*(MMULT(--(L6:Q26=13),TRANSPOSE(COLUMN(L6:Q6)^0))>0)*R6:R26)} -> 46 | AA7: {=SUM((MMULT(--(L6:Q26=1),TRANSPOSE(COLUMN(L6:Q6)^0))>0)*(MMULT(--(L6:Q26=15),TRANSPOSE(COLUMN(L6:Q6)^0))>0)*R6:R26)} -> 53
A8: 23-09-24-184809.435-04.jpg | B8: TRASH | N8: 9 | O8: 10 | Q8: 15 | R8: {=COUNTIF($D$4:$D$3228&"|"&$E$4:$E$3228&"|"&$F$4:$F$3228&"|"&$G$4:$G$3228&"|"&$H$4:$H$3228&"|"&$I$4:$I$3228,$L8&"|"&$M8&"|"&$N8&"|"&$O8&"|"&$P8&"|"&$Q8)} -> 12 | U8: M2 | X8: {=SUM((MMULT(--(L6:Q26=2),TRANSPOSE(COLUMN(L6:Q6)^0))>0)*(MMULT(--(L6:Q26=9),TRANSPOSE(COLUMN(L6:Q6)^0))>0)*R6:R26)} -> 72 | Y8: {=SUM((MMULT(--(L6:Q26=2),TRANSPOSE(COLUMN(L6:Q6)^0))>0)*(MMULT(--(L6:Q26=10),TRANSPOSE(COLUMN(L6:Q6)^0))>0)*R6:R26)} -> 0 | Z8: {=SUM((MMULT(--(L6:Q26=2),TRANSPOSE(COLUMN(L6:Q6)^0))>0)*(MMULT(--(L6:Q26=13),TRANSPOSE(COLUMN(L6:Q6)^0))>0)*R6:R26)} -> 113 | AA8: {=SUM((MMULT(--(L6:Q26=2),TRANSPOSE(COLUMN(L6:Q6)^0))>0)*(MMULT(--(L6:Q26=15),TRANSPOSE(COLUMN(L6:Q6)^0))>0)*R6:R26)} -> 42
A9: 23-09-24-184811.625-05.jpg | B9: TRASH | N9: 9 | Q9: 15 | R9: {=COUNTIF($D$4:$D$3228&"|"&$E$4:$E$3228&"|"&$F$4:$F$3228&"|"&$G$4:$G$3228&"|"&$H$4:$H$3228&"|"&$I$4:$I$3228,$L9&"|"&$M9&"|"&$N9&"|"&$O9&"|"&$P9&"|"&$Q9)} -> 2 | U9: M9 | Y9: {=SUM((MMULT(--(L6:Q26=9),TRANSPOSE(COLUMN(L6:Q6)^0))>0)*(MMULT(--(L6:Q26=10),TRANSPOSE(COLUMN(L6:Q6)^0))>0)*R6:R26)} -> 32 | Z9: {=SUM((MMULT(--(L6:Q26=9),TRANSPOSE(COLUMN(L6:Q6)^0))>0)*(MMULT(--(L6:Q26=13),TRANSPOSE(COLUMN(L6:Q6)^0))>0)*R6:R26)} -> 106 | AA9: {=SUM((MMULT(--(L6:Q26=9),TRANSPOSE(COLUMN(L6:Q6)^0))>0)*(MMULT(--(L6:Q26=15),TRANSPOSE(COLUMN(L6:Q6)^0))>0)*R6:R26)} -> 77
A10: 23-09-24-184813.812-06.jpg | B10: TRASH | N10: 9 | O10: 10 | P10: 13 | Q10: 15 | R10: {=COUNTIF($D$4:$D$3228&"|"&$E$4:$E$3228&"|"&$F$4:$F$3228&"|"&$G$4:$G$3228&"|"&$H$4:$H$3228&"|"&$I$4:$I$3228,$L10&"|"&$M10&"|"&$N10&"|"&$O10&"|"&$P10&"|"&$Q10)} -> 4 | U10: M10 | Z10: {=SUM((MMULT(--(L6:Q26=10),TRANSPOSE(COLUMN(L6:Q6)^0))>0)*(MMULT(--(L6:Q26=13),TRANSPOSE(COLUMN(L6:Q6)^0))>0)*R6:R26)} -> 7 | AA10: {=SUM((MMULT(--(L6:Q26=10),TRANSPOSE(COLUMN(L6:Q6)^0))>0)*(MMULT(--(L6:Q26=15),TRANSPOSE(COLUMN(L6:Q6)^0))>0)*R6:R26)} -> 16
A11: 23-09-24-184815.950-07.jpg | B11: TRASH | N11: 9 | O11: 10 | P11: 13 | R11: {=COUNTIF($D$4:$D$3228&"|"&$E$4:$E$3228&"|"&$F$4:$F$3228&"|"&$G$4:$G$3228&"|"&$H$4:$H$3228&"|"&$I$4:$I$3228,$L11&"|"&$M11&"|"&$N11&"|"&$O11&"|"&$P11&"|"&$Q11)} -> 3 | U11: M13 | AA11: {=SUM((MMULT(--(L6:Q26=13),TRANSPOSE(COLUMN(L6:Q6)^0))>0)*(MMULT(--(L6:Q26=15),TRANSPOSE(COLUMN(L6:Q6)^0))>0)*R6:R26)} -> 61
A12: 23-09-24-184818.125-08.jpg | B12: TRASH | N12: 9 | P12: 13 | Q12: 15 | R12: {=COUNTIF($D$4:$D$3228&"|"&$E$4:$E$3228&"|"&$F$4:$F$3228&"|"&$G$4:$G$3228&"|"&$H$4:$H$3228&"|"&$I$4:$I$3228,$L12&"|"&$M12&"|"&$N12&"|"&$O12&"|"&$P12&"|"&$Q12)} -> 6 | U12: M15
A13: 23-09-24-184820.297-09.jpg | B13: TRASH | L13: 1 | N13: 9 | P13: 13 | Q13: 15 | R13: {=COUNTIF($D$4:$D$3228&"|"&$E$4:$E$3228&"|"&$F$4:$F$3228&"|"&$G$4:$G$3228&"|"&$H$4:$H$3228&"|"&$I$4:$I$3228,$L13&"|"&$M13&"|"&$N13&"|"&$O13&"|"&$P13&"|"&$Q13)} -> 9
A14: 23-09-24-184822.430-10.jpg | B14: TRASH | L14: 1 | M14: 2 | N14: 9 | P14: 13 | Q14: 15 | R14: {=COUNTIF($D$4:$D$3228&"|"&$E$4:$E$3228&"|"&$F$4:$F$3228&"|"&$G$4:$G$3228&"|"&$H$4:$H$3228&"|"&$I$4:$I$3228,$L14&"|"&$M14&"|"&$N14&"|"&$O14&"|"&$P14&"|"&$Q14)} -> 30
A15: 23-09-24-184824.614-11.jpg | B15: NO | M15: 2 | N15: 9 | P15: 13 | Q15: 15 | R15: {=COUNTIF($D$4:$D$3228&"|"&$E$4:$E$3228&"|"&$F$4:$F$3228&"|"&$G$4:$G$3228&"|"&$H$4:$H$3228&"|"&$I$4:$I$3228,$L15&"|"&$M15&"|"&$N15&"|"&$O15&"|"&$P15&"|"&$Q15)} -> 12
A16: 23-09-24-184826.794-12.jpg | B16: YES | C16: 1 | G16: 10 | M16: 2 | N16: 9 | P16: 13 | R16: {=COUNTIF($D$4:$D$3228&"|"&$E$4:$E$3228&"|"&$F$4:$F$3228&"|"&$G$4:$G$3228&"|"&$H$4:$H$3228&"|"&$I$4:$I$3228,$L16&"|"&$M16&"|"&$N16&"|"&$O16&"|"&$P16&"|"&$Q16)} -> 29
A17: 23-09-24-184828.982-13.jpg | B17: YES | C17: 1 | G17: 10 | M17: 2 | P17: 13 | R17: {=COUNTIF($D$4:$D$3228&"|"&$E$4:$E$3228&"|"&$F$4:$F$3228&"|"&$G$4:$G$3228&"|"&$H$4:$H$3228&"|"&$I$4:$I$3228,$L17&"|"&$M17&"|"&$N17&"|"&$O17&"|"&$P17&"|"&$Q17)} -> 41
A18: 23-09-24-184831.181-14.jpg | B18: YES | C18: 1 | G18: 10 | P18: 13 | R18: {=COUNTIF($D$4:$D$3228&"|"&$E$4:$E$3228&"|"&$F$4:$F$3228&"|"&$G$4:$G$3228&"|"&$H$4:$H$3228&"|"&$I$4:$I$3228,$L18&"|"&$M18&"|"&$N18&"|"&$O18&"|"&$P18&"|"&$Q18)} -> 15
A19: 23-09-24-184833.380-15.jpg | B19: YES | C19: 1 | G19: 10 | L19: 1 | M19: 2 | N19: 9 | P19: 13 | R19: {=COUNTIF($D$4:$D$3228&"|"&$E$4:$E$3228&"|"&$F$4:$F$3228&"|"&$G$4:$G$3228&"|"&$H$4:$H$3228&"|"&$I$4:$I$3228,$L19&"|"&$M19&"|"&$N19&"|"&$O19&"|"&$P19&"|"&$Q19)} -> 1
A20: 23-09-24-184835.595-16.jpg | B20: YES | C20: 1 | G20: 10 | L20: 1 | Q20: 15 | R20: {=COUNTIF($D$4:$D$3228&"|"&$E$4:$E$3228&"|"&$F$4:$F$3228&"|"&$G$4:$G$3228&"|"&$H$4:$H$3228&"|"&$I$4:$I$3228,$L20&"|"&$M20&"|"&$N20&"|"&$O20&"|"&$P20&"|"&$Q20)} -> 12
A21: 23-09-24-184837.791-17.jpg | B21: YES | C21: 1 | G21: 10 | N21: 9 | P21: 13 | R21: {=COUNTIF($D$4:$D$3228&"|"&$E$4:$E$3228&"|"&$F$4:$F$3228&"|"&$G$4:$G$3228&"|"&$H$4:$H$3228&"|"&$I$4:$I$3228,$L21&"|"&$M21&"|"&$N21&"|"&$O21&"|"&$P21&"|"&$Q21)} -> 6
A22: 23-09-24-184839.980-18.jpg | B22: YES | C22: 1 | G22: 10 | N22: 9 | R22: {=COUNTIF($D$4:$D$3228&"|"&$E$4:$E$3228&"|"&$F$4:$F$3228&"|"&$G$4:$G$3228&"|"&$H$4:$H$3228&"|"&$I$4:$I$3228,$L22&"|"&$M22&"|"&$N22&"|"&$O22&"|"&$P22&"|"&$Q22)} -> 1
A23: 23-09-24-184842.172-19.jpg | B23: YES | C23: 1 | G23: 10 | L23: 1 | N23: 9 | P23: 13 | R23: {=COUNTIF($D$4:$D$3228&"|"&$E$4:$E$3228&"|"&$F$4:$F$3228&"|"&$G$4:$G$3228&"|"&$H$4:$H$3228&"|"&$I$4:$I$3228,$L23&"|"&$M23&"|"&$N23&"|"&$O23&"|"&$P23&"|"&$Q23)} -> 6
A24: 23-09-24-184844.352-20.jpg | B24: YES | C24: 1 | G24: 10 | L24: 1 | N24: 9 | R24: {=COUNTIF($D$4:$D$3228&"|"&$E$4:$E$3228&"|"&$F$4:$F$3228&"|"&$G$4:$G$3228&"|"&$H$4:$H$3228&"|"&$I$4:$I$3228,$L24&"|"&$M24&"|"&$N24&"|"&$O24&"|"&$P24&"|"&$Q24)} -> 1
A25: 23-09-24-184846.542-21.jpg | B25: YES | C25: 1 | G25: 10 | L25: 1 | R25: {=COUNTIF($D$4:$D$3228&"|"&$E$4:$E$3228&"|"&$F$4:$F$3228&"|"&$G$4:$G$3228&"|"&$H$4:$H$3228&"|"&$I$4:$I$3228,$L25&"|"&$M25&"|"&$N25&"|"&$O25&"|"&$P25&"|"&$Q25)} -> 14
A26: 23-09-24-184848.737-22.jpg | B26: YES | C26: 1 | G26: 10 | L26: 1 | N26: 9 | Q26: 15 | R26: {=COUNTIF($D$4:$D$3228&"|"&$E$4:$E$3228&"|"&$F$4:$F$3228&"|"&$G$4:$G$3228&"|"&$H$4:$H$3228&"|"&$I$4:$I$3228,$L26&"|"&$M26&"|"&$N26&"|"&$O26&"|"&$P26&"|"&$Q26)} -> 2
A27: 23-09-24-184850.936-23.jpg | B27: YES | C27: 1 | G27: 10 | O27: 10 | Q27: 15 | R27: {=COUNTIF($D$4:$D$3228&"|"&$E$4:$E$3228&"|"&$F$4:$F$3228&"|"&$G$4:$G$3228&"|"&$H$4:$H$3228&"|"&$I$4:$I$3228,$L27&"|"&$M27&"|"&$N27&"|"&$O27&"|"&$P27&"|"&$Q27)} -> 5
A28: 23-09-24-184853.140-24.jpg | B28: YES | C28: 1 | G28: 10 | M28: 2 | N28: 9 | R28: {=COUNTIF($D$4:$D$3228&"|"&$E$4:$E$3228&"|"&$F$4:$F$3228&"|"&$G$4:$G$3228&"|"&$H$4:$H$3228&"|"&$I$4:$I$3228,$L28&"|"&$M28&"|"&$N28&"|"&$O28&"|"&$P28&"|"&$Q28)} -> 7
A29: 23-09-24-184855.332-25.jpg | B29: NO | L29: 1 | P29: 13 | Q29: 15 | R29: {=COUNTIF($D$4:$D$3228&"|"&$E$4:$E$3228&"|"&$F$4:$F$3228&"|"&$G$4:$G$3228&"|"&$H$4:$H$3228&"|"&$I$4:$I$3228,$L29&"|"&$M29&"|"&$N29&"|"&$O29&"|"&$P29&"|"&$Q29)} -> 5
A30: 23-09-24-184857.523-26.jpg | B30: NO | L30: 1 | P30: 13 | R30: {=COUNTIF($D$4:$D$3228&"|"&$E$4:$E$3228&"|"&$F$4:$F$3228&"|"&$G$4:$G$3228&"|"&$H$4:$H$3228&"|"&$I$4:$I$3228,$L30&"|"&$M30&"|"&$N30&"|"&$O30&"|"&$P30&"|"&$Q30)} -> 2
A31: 23-09-24-184859.711-27.jpg | B31: NO | L31: 1 | N31: 9 | R31: {=COUNTIF($D$4:$D$3228&"|"&$E$4:$E$3228&"|"&$F$4:$F$3228&"|"&$G$4:$G$3228&"|"&$H$4:$H$3228&"|"&$I$4:$I$3228,$L31&"|"&$M31&"|"&$N31&"|"&$O31&"|"&$P31&"|"&$Q31)} -> 1
A32: 23-09-24-184901.901-28.jpg | B32: NO | L32: 1 | R32: {=COUNTIF($D$4:$D$3228&"|"&$E$4:$E$3228&"|"&$F$4:$F$3228&"|"&$G$4:$G$3228&"|"&$H$4:$H$3228&"|"&$I$4:$I$3228,$L32&"|"&$M32&"|"&$N32&"|"&$O32&"|"&$P32&"|"&$Q32)} -> 1
A33: 23-09-24-184904.073-29.jpg | B33: NO | Q33: 15 | R33: {=COUNTIF($D$4:$D$3228&"|"&$E$4:$E$3228&"|"&$F$4:$F$3228&"|"&$G$4:$G$3228&"|"&$H$4:$H$3228&"|"&$I$4:$I$3228,$L33&"|"&$M33&"|"&$N33&"|"&$O33&"|"&$P33&"|"&$Q33)} -> 1
A34: 23-09-24-184906.265-30.jpg | B34: NO | M34: 2 | R34: {=COUNTIF($D$4:$D$3228&"|"&$E$4:$E$3228&"|"&$F$4:$F$3228&"|"&$G$4:$G$3228&"|"&$H$4:$H$3228&"|"&$I$4:$I$3228,$L34&"|"&$M34&"|"&$N34&"|"&$O34&"|"&$P34&"|"&$Q34)} -> 14
A35: 23-09-24-184908.434-31.jpg | B35: NO | M35: 2 | N35: 9 | O35: 10 | R35: {=COUNTIF($D$4:$D$3228&"|"&$E$4:$E$3228&"|"&$F$4:$F$3228&"|"&$G$4:$G$3228&"|"&$H$4:$H$3228&"|"&$I$4:$I$3228,$L35&"|"&$M35&"|"&$N35&"|"&$O35&"|"&$P35&"|"&$Q35)} -> 1
A36: 23-09-24-184910.623-32.jpg | B36: NO | R36: =SUm(R6:R35) -> 307
A37: 23-09-24-184912.802-33.jpg | B37: NO | R37: =$C$2 -> 307
A38: 23-09-24-184914.980-34.jpg | B38: NO
A39: 23-09-24-184917.159-35.jpg | B39: NO
A40: 23-09-24-184919.343-36.jpg | B40: NO
...

Sheet NI202409_CAP-EC_D05
A1: The Nice Cape East Cove | B1: Département : | C1: Alpes Maritimes | D1: Ville : | E1: Nice | F1: Site : | G1: Cap de Nice, These | H1: Date : | I1: 45560 | J1: ID : | K1: NI202409_CAP-EC_D05 | L1: Camera : | M1: Picam HQ 170°Lens (amazon) (R6 - Rack Cata) | N1: NB Img : | O1: =COUNTA(A4:A5373)-COUNTIF(B:B,"TRAVEL BACK")-COUNTIF(B:B,"COLOR SAMPLE")-COUNTIF(B:B,"TRASH") -> 1092
A2: Stats | B2: Img avec mire(s) : | C2: =COUNTIF(B4:B7868,"YES") -> 366 | D2: 1 M : | E2: =COUNTIF(C4:C7868,"1") -> 267 | F2: 2 M : | G2: =COUNTIF(C4:C7868,"2") -> 49 | H2: 3 M : | I2: =COUNTIF(C4:C7868,"3") -> 23 | J2: 4 M : | K2: =COUNTIF(C4:C7868,"4") -> 17 | L2: 5 M : | M2: =COUNTIF(C4:C7868,"5") -> 10 | N2: 6 M : | O2: =COUNTIF(C4:C7868,"6") -> 0 | P2: X Ms : | Q2: =G2+I2+K2+M2+O2 -> 99
A3: Images name | B3: Mire ? | C3: Quantité | D3: M1 | E3: M2 | F3: M9 | G3: M10 | H3: M13 | I3: M15 | J3: M1 occ: | K3: =COUNTIF(D4:J7868,"1") -> 107 | L3: M2 occ: | M3: =COUNTIF(D4:J7868,"2") -> 107 | N3: M9 occ: | O3: =COUNTIF(D4:J7868,"9") -> 101 | P3: M10 occ: | Q3: =COUNTIF(D4:J7868,"10") -> 50 | R3: M13 occ: | S3: =COUNTIF(D4:J7868,"13") -> 121 | T3: M15 occ: | U3: =COUNTIF(D4:J7868,"15") -> 66
A4: 24-09-24-002646.025-00.jpg | B4: YES | C4: 1 | D4: 1 | L4: Combinaisons visibles de mires sur les images
A5: 24-09-24-002648.130-01.jpg | B5: YES | C5: 1 | D5: 1 | L5: {=UNIQUE(D4:I4979)} -> 1 | R5: {=COUNTIF($D$4:$D$3339&"|"&$E$4:$E$3339&"|"&$F$4:$F$3339&"|"&$G$4:$G$3339&"|"&$H$4:$H$3339&"|"&$I$4:$I$3339,$L5&"|"&$M5&"|"&$N5&"|"&$O5&"|"&$P5&"|"&$Q5)} -> 71 | V5: M1 | W5: M2 | X5: M9 | Y5: M10 | Z5: M13 | AA5: M15
A6: 24-09-24-002650.304-02.jpg | B6: YES | C6: 1 | D6: 1 | U6: M1 | W6: {=SUM((MMULT(--(L5:Q25=1),TRANSPOSE(COLUMN(L5:Q5)^0))>0)*(MMULT(--(L5:Q25=2),TRANSPOSE(COLUMN(L5:Q5)^0))>0)*R5:R25)} -> 9 | X6: {=SUM((MMULT(--(L5:Q25=1),TRANSPOSE(COLUMN(L5:Q5)^0))>0)*(MMULT(--(L5:Q25=9),TRANSPOSE(COLUMN(L5:Q5)^0))>0)*R5:R25)} -> 12 | Y6: {=SUM((MMULT(--(L5:Q25=1),TRANSPOSE(COLUMN(L5:Q5)^0))>0)*(MMULT(--(L5:Q25=10),TRANSPOSE(COLUMN(L5:Q5)^0))>0)*R5:R25)} -> 0 | Z6: {=SUM((MMULT(--(L5:Q25=1),TRANSPOSE(COLUMN(L5:Q5)^0))>0)*(MMULT(--(L5:Q25=13),TRANSPOSE(COLUMN(L5:Q5)^0))>0)*R5:R25)} -> 27 | AA6: {=SUM((MMULT(--(L5:Q25=1),TRANSPOSE(COLUMN(L5:Q5)^0))>0)*(MMULT(--(L5:Q25=15),TRANSPOSE(COLUMN(L5:Q5)^0))>0)*R5:R25)} -> 25
A7: 24-09-24-002652.408-03.jpg | B7: YES | C7: 1 | D7: 1 | Q7: 15 | R7: {=COUNTIF($D$4:$D$3339&"|"&$E$4:$E$3339&"|"&$F$4:$F$3339&"|"&$G$4:$G$3339&"|"&$H$4:$H$3339&"|"&$I$4:$I$3339,$L7&"|"&$M7&"|"&$N7&"|"&$O7&"|"&$P7&"|"&$Q7)} -> 23 | U7: M2 | X7: {=SUM((MMULT(--(L5:Q25=2),TRANSPOSE(COLUMN(L5:Q5)^0))>0)*(MMULT(--(L5:Q25=9),TRANSPOSE(COLUMN(L5:Q5)^0))>0)*R5:R25)} -> 35 | Y7: {=SUM((MMULT(--(L5:Q25=2),TRANSPOSE(COLUMN(L5:Q5)^0))>0)*(MMULT(--(L5:Q25=10),TRANSPOSE(COLUMN(L5:Q5)^0))>0)*R5:R25)} -> 0 | Z7: {=SUM((MMULT(--(L5:Q25=2),TRANSPOSE(COLUMN(L5:Q5)^0))>0)*(MMULT(--(L5:Q25=13),TRANSPOSE(COLUMN(L5:Q5)^0))>0)*R5:R25)} -> 47 | AA7: {=SUM((MMULT(--(L5:Q25=2),TRANSPOSE(COLUMN(L5:Q5)^0))>0)*(MMULT(--(L5:Q25=15),TRANSPOSE(COLUMN(L5:Q5)^0))>0)*R5:R25)} -> 18
A8: 24-09-24-002654.596-04.jpg | B8: YES | C8: 1 | D8: 1 | N8: 9 | R8: {=COUNTIF($D$4:$D$3339&"|"&$E$4:$E$3339&"|"&$F$4:$F$3339&"|"&$G$4:$G$3339&"|"&$H$4:$H$3339&"|"&$I$4:$I$3339,$L8&"|"&$M8&"|"&$N8&"|"&$O8&"|"&$P8&"|"&$Q8)} -> 39 | U8: M9 | Y8: {=SUM((MMULT(--(L5:Q25=9),TRANSPOSE(COLUMN(L5:Q5)^0))>0)*(MMULT(--(L5:Q25=10),TRANSPOSE(COLUMN(L5:Q5)^0))>0)*R5:R25)} -> 0 | Z8: {=SUM((MMULT(--(L5:Q25=9),TRANSPOSE(COLUMN(L5:Q5)^0))>0)*(MMULT(--(L5:Q25=13),TRANSPOSE(COLUMN(L5:Q5)^0))>0)*R5:R25)} -> 51 | AA8: {=SUM((MMULT(--(L5:Q25=9),TRANSPOSE(COLUMN(L5:Q5)^0))>0)*(MMULT(--(L5:Q25=15),TRANSPOSE(COLUMN(L5:Q5)^0))>0)*R5:R25)} -> 25
A9: 24-09-24-002656.812-05.jpg | B9: YES | C9: 1 | D9: 1 | O9: 10 | R9: {=COUNTIF($D$4:$D$3339&"|"&$E$4:$E$3339&"|"&$F$4:$F$3339&"|"&$G$4:$G$3339&"|"&$H$4:$H$3339&"|"&$I$4:$I$3339,$L9&"|"&$M9&"|"&$N9&"|"&$O9&"|"&$P9&"|"&$Q9)} -> 46 | U9: M10 | Z9: {=SUM((MMULT(--(L5:Q25=10),TRANSPOSE(COLUMN(L5:Q5)^0))>0)*(MMULT(--(L5:Q25=13),TRANSPOSE(COLUMN(L5:Q5)^0))>0)*R5:R25)} -> 0 | AA9: {=SUM((MMULT(--(L5:Q25=10),TRANSPOSE(COLUMN(L5:Q5)^0))>0)*(MMULT(--(L5:Q25=15),TRANSPOSE(COLUMN(L5:Q5)^0))>0)*R5:R25)} -> 0
A10: 24-09-24-002659.010-06.jpg | B10: YES | C10: 1 | D10: 1 | N10: 9 | P10: 13 | R10: {=COUNTIF($D$4:$D$3339&"|"&$E$4:$E$3339&"|"&$F$4:$F$3339&"|"&$G$4:$G$3339&"|"&$H$4:$H$3339&"|"&$I$4:$I$3339,$L10&"|"&$M10&"|"&$N10&"|"&$O10&"|"&$P10&"|"&$Q10)} -> 12 | U10: M13 | AA10: {=SUM((MMULT(--(L5:Q25=13),TRANSPOSE(COLUMN(L5:Q5)^0))>0)*(MMULT(--(L5:Q25=15),TRANSPOSE(COLUMN(L5:Q5)^0))>0)*R5:R25)} -> 29
A11: 24-09-24-002701.211-07.jpg | B11: YES | C11: 1 | D11: 1 | M11: 2 | N11: 9 | P11: 13 | R11: {=COUNTIF($D$4:$D$3339&"|"&$E$4:$E$3339&"|"&$F$4:$F$3339&"|"&$G$4:$G$3339&"|"&$H$4:$H$3339&"|"&$I$4:$I$3339,$L11&"|"&$M11&"|"&$N11&"|"&$O11&"|"&$P11&"|"&$Q11)} -> 16 | U11: M15
A12: 24-09-24-002703.420-08.jpg | B12: YES | C12: 1 | D12: 1 | L12: 1 | M12: 2 | N12: 9 | P12: 13 | Q12: 15 | R12: {=COUNTIF($D$4:$D$3339&"|"&$E$4:$E$3339&"|"&$F$4:$F$3339&"|"&$G$4:$G$3339&"|"&$H$4:$H$3339&"|"&$I$4:$I$3339,$L12&"|"&$M12&"|"&$N12&"|"&$O12&"|"&$P12&"|"&$Q12)} -> 7
A13: 24-09-24-002705.632-09.jpg | B13: YES | C13: 1 | D13: 1 | L13: 1 | N13: 9 | P13: 13 | Q13: 15 | R13: {=COUNTIF($D$4:$D$3339&"|"&$E$4:$E$3339&"|"&$F$4:$F$3339&"|"&$G$4:$G$3339&"|"&$H$4:$H$3339&"|"&$I$4:$I$3339,$L13&"|"&$M13&"|"&$N13&"|"&$O13&"|"&$P13&"|"&$Q13)} -> 4
A14: 24-09-24-002707.745-10.jpg | B14: YES | C14: 1 | D14: 1 | L14: 1 | Q14: 15 | R14: {=COUNTIF($D$4:$D$3339&"|"&$E$4:$E$3339&"|"&$F$4:$F$3339&"|"&$G$4:$G$3339&"|"&$H$4:$H$3339&"|"&$I$4:$I$3339,$L14&"|"&$M14&"|"&$N14&"|"&$O14&"|"&$P14&"|"&$Q14)} -> 8
A15: 24-09-24-002709.962-11.jpg | B15: YES | C15: 1 | D15: 1 | L15: 1 | P15: 13 | Q15: 15 | R15: {=COUNTIF($D$4:$D$3339&"|"&$E$4:$E$3339&"|"&$F$4:$F$3339&"|"&$G$4:$G$3339&"|"&$H$4:$H$3339&"|"&$I$4:$I$3339,$L15&"|"&$M15&"|"&$N15&"|"&$O15&"|"&$P15&"|"&$Q15)} -> 4
A16: 24-09-24-002712.075-12.jpg | B16: YES | C16: 1 | D16: 1 | L16: 1 | M16: 2 | P16: 13 | Q16: 15 | R16: {=COUNTIF($D$4:$D$3339&"|"&$E$4:$E$3339&"|"&$F$4:$F$3339&"|"&$G$4:$G$3339&"|"&$H$4:$H$3339&"|"&$I$4:$I$3339,$L16&"|"&$M16&"|"&$N16&"|"&$O16&"|"&$P16&"|"&$Q16)} -> 2
A17: 24-09-24-002714.268-13.jpg | B17: YES | C17: 1 | D17: 1 | M17: 2 | N17: 9 | P17: 13 | Q17: 15 | R17: {=COUNTIF($D$4:$D$3339&"|"&$E$4:$E$3339&"|"&$F$4:$F$3339&"|"&$G$4:$G$3339&"|"&$H$4:$H$3339&"|"&$I$4:$I$3339,$L17&"|"&$M17&"|"&$N17&"|"&$O17&"|"&$P17&"|"&$Q17)} -> 9
A18: 24-09-24-002716.494-14.jpg | B18: YES | C18: 1 | D18: 1 | M18: 2 | N18: 9 | R18: {=COUNTIF($D$4:$D$3339&"|"&$E$4:$E$3339&"|"&$F$4:$F$3339&"|"&$G$4:$G$3339&"|"&$H$4:$H$3339&"|"&$I$4:$I$3339,$L18&"|"&$M18&"|"&$N18&"|"&$O18&"|"&$P18&"|"&$Q18)} -> 3
A19: 24-09-24-002719.575-15.jpg | B19: YES | C19: 1 | D19: 1 | L19: 1 | P19: 13 | R19: {=COUNTIF($D$4:$D$3339&"|"&$E$4:$E$3339&"|"&$F$4:$F$3339&"|"&$G$4:$G$3339&"|"&$H$4:$H$3339&"|"&$I$4:$I$3339,$L19&"|"&$M19&"|"&$N19&"|"&$O19&"|"&$P19&"|"&$Q19)} -> 9
A20: 24-09-24-002721.707-16.jpg | B20: YES | C20: 1 | D20: 1 | J20: COLORCHECKER | N20: 9 | P20: 13 | Q20: 15 | R20: {=COUNTIF($D$4:$D$3339&"|"&$E$4:$E$3339&"|"&$F$4:$F$3339&"|"&$G$4:$G$3339&"|"&$H$4:$H$3339&"|"&$I$4:$I$3339,$L20&"|"&$M20&"|"&$N20&"|"&$O20&"|"&$P20&"|"&$Q20)} -> 2
A21: 24-09-24-002723.879-17.jpg | B21: YES | C21: 1 | D21: 1 | J21: COLORCHECKER | M21: 2 | P21: 13 | R21: {=COUNTIF($D$4:$D$3339&"|"&$E$4:$E$3339&"|"&$F$4:$F$3339&"|"&$G$4:$G$3339&"|"&$H$4:$H$3339&"|"&$I$4:$I$3339,$L21&"|"&$M21&"|"&$N21&"|"&$O21&"|"&$P21&"|"&$Q21)} -> 13
A22: 24-09-24-002726.072-18.jpg | B22: YES | C22: 1 | D22: 1 | J22: COLORCHECKER | N22: 9 | Q22: 15 | R22: {=COUNTIF($D$4:$D$3339&"|"&$E$4:$E$3339&"|"&$F$4:$F$3339&"|"&$G$4:$G$3339&"|"&$H$4:$H$3339&"|"&$I$4:$I$3339,$L22&"|"&$M22&"|"&$N22&"|"&$O22&"|"&$P22&"|"&$Q22)} -> 3
A23: 24-09-24-002728.262-19.jpg | B23: YES | C23: 1 | D23: 1 | M23: 2 | R23: {=COUNTIF($D$4:$D$3339&"|"&$E$4:$E$3339&"|"&$F$4:$F$3339&"|"&$G$4:$G$3339&"|"&$H$4:$H$3339&"|"&$I$4:$I$3339,$L23&"|"&$M23&"|"&$N23&"|"&$O23&"|"&$P23&"|"&$Q23)} -> 52
A24: 24-09-24-002730.462-20.jpg | B24: NO | J24: COLORCHECKER | P24: 13 | Q24: 15 | R24: {=COUNTIF($D$4:$D$3339&"|"&$E$4:$E$3339&"|"&$F$4:$F$3339&"|"&$G$4:$G$3339&"|"&$H$4:$H$3339&"|"&$I$4:$I$3339,$L24&"|"&$M24&"|"&$N24&"|"&$O24&"|"&$P24&"|"&$Q24)} -> 1
A25: 24-09-24-002732.691-21.jpg | B25: NO | J25: COLORCHECKER | L25: 1 | N25: 9 | P25: 13 | R25: {=COUNTIF($D$4:$D$3339&"|"&$E$4:$E$3339&"|"&$F$4:$F$3339&"|"&$G$4:$G$3339&"|"&$H$4:$H$3339&"|"&$I$4:$I$3339,$L25&"|"&$M25&"|"&$N25&"|"&$O25&"|"&$P25&"|"&$Q25)} -> 1
A26: 24-09-24-002735.688-22.jpg | B26: NO | J26: COLORCHECKER | L26: 1 | M26: 2 | N26: 9 | P26: 13 | R26: {=COUNTIF($D$4:$D$3339&"|"&$E$4:$E$3339&"|"&$F$4:$F$3339&"|"&$G$4:$G$3339&"|"&$H$4:$H$3339&"|"&$I$4:$I$3339,$L26&"|"&$M26&"|"&$N26&"|"&$O26&"|"&$P26&"|"&$Q26)} -> 1
A27: 24-09-24-002737.892-23.jpg | B27: YES | C27: 1 | I27: 15 | J27: COLORCHECKER | P27: 13 | R27: {=COUNTIF($D$4:$D$3339&"|"&$E$4:$E$3339&"|"&$F$4:$F$3339&"|"&$G$4:$G$3339&"|"&$H$4:$H$3339&"|"&$I$4:$I$3339,$L27&"|"&$M27&"|"&$N27&"|"&$O27&"|"&$P27&"|"&$Q27)} -> 36
A28: 24-09-24-002740.092-24.jpg | B28: YES | C28: 1 | I28: 15 | J28: COLORCHECKER | M28: 2 | N28: 9 | O28: 10 | P28: 13 | R28: {=COUNTIF($D$4:$D$3339&"|"&$E$4:$E$3339&"|"&$F$4:$F$3339&"|"&$G$4:$G$3339&"|"&$H$4:$H$3339&"|"&$I$4:$I$3339,$L28&"|"&$M28&"|"&$N28&"|"&$O28&"|"&$P28&"|"&$Q28)} -> 1
A29: 24-09-24-002742.312-25.jpg | B29: YES | C29: 1 | I29: 15 | J29: COLORCHECKER | M29: 2 | N29: 9 | O29: 10 | P29: 13 | Q29: 15 | R29: {=COUNTIF($D$4:$D$3339&"|"&$E$4:$E$3339&"|"&$F$4:$F$3339&"|"&$G$4:$G$3339&"|"&$H$4:$H$3339&"|"&$I$4:$I$3339,$L29&"|"&$M29&"|"&$N29&"|"&$O29&"|"&$P29&"|"&$Q29)} -> 3
A30: 24-09-24-002744.511-26.jpg | B30: YES | C30: 1 | I30: 15 | J30: COLORCHECKER | R30: =SUm(R5:R29) -> 366
A31: 24-09-24-002746.617-27.jpg | B31: YES | C31: 1 | I31: 15 | J31: COLORCHECKER | R31: =$C$2 -> 366
A32: 24-09-24-002748.799-28.jpg | B32: YES | C32: 1 | I32: 15 | J32: COLORCHECKER
A33: 24-09-24-002751.986-29.jpg | B33: YES | C33: 1 | I33: 15 | J33: COLORCHECKER
A34: 24-09-24-002754.203-30.jpg | B34: YES | C34: 1 | I34: 15 | J34: COLORCHECKER | K34: COLORCHECKER
A35: 24-09-24-002756.391-31.jpg | B35: YES | C35: 1 | I35: 15 | J35: COLORCHECKER | K35: COLORCHECKER
A36: 24-09-24-002758.592-32.jpg | B36: YES | C36: 1 | I36: 15 | J36: COLORCHECKER | K36: COLORCHECKER
A37: 24-09-24-002800.792-33.jpg | B37: NO | J37: COLORCHECKER
A38: 24-09-24-002802.992-34.jpg | B38: NO | J38: COLORCHECKER
A39: 24-09-24-002805.105-35.jpg | B39: NO | J39: COLORCHECKER
A40: 24-09-24-002807.273-36.jpg | B40: NO | J40: COLORCHECKER
...

Sheet NI202409_CAP-EC_D06
A1: The Nice Cape East Cove | B1: Département : | C1: Alpes Maritimes | D1: Ville : | E1: Nice | F1: Site : | G1: Cap de Nice, These | H1: Date : | I1: 45560 | J1: ID : | K1: NI202409_CAP-EC_D06 | L1: Camera : | M1: Picam HQ Lens (commonlands GoPro 2.6mm 120°) (R7 - Rack Main) | N1: NB Img : | O1: =COUNTA(A4:A5373)-COUNTIF(B:B,"TRAVEL BACK")-COUNTIF(B:B,"COLOR SAMPLE")-COUNTIF(B:B,"TRASH") -> 634
